Workbook
Name Summary: #REF!

Sheet Summary
B1: TaiTai Creamery - Jubilee Hills
B2: Swiggy Summary - July 2025
B4: Details | C4: 1st to 5th | D4: 6th to 12th | E4: 13th to 19th | F4: 20th to 26th | G4: 27th to 31st | H4: Total
B6: No.of orders | C6: 15 | D6: 33 | E6: 27 | F6: 33 | H6: =SUM(C6:G6)
B8: Total Income (Number that you see on Swiggy dashboard) | C8: =Cashflow!C10 | D8: =Cashflow!D10 | E8: =Cashflow!E10 | F8: =Cashflow!F10 | G8: =Cashflow!G10 | H8: =SUM(C8:G8)
B10: Avg. order value | C10: =IFERROR(C8/C60,) | D10: =IFERROR(D8/D6,0) | E10: =IFERROR(E8/E6,0) | F10: =IFERROR(F8/F6,0) | G10: =IFERROR(G8/G6,0) | H10: =IFERROR(H8/H6,0)
B12: No of Disputed Orders | C12: 0 | D12: 0 | E12: 0 | F12: 0 | G12: 0 | H12: =SUM(C12:G12)
B14: Refund amount for disputed orders | C14: =Cashflow!C13 | D14: =Cashflow!D13 | E14: =Cashflow!E13 | F14: =Cashflow!F13 | G14: =Cashflow!G13 | H14: =SUM(C14:G14)
B15: Discounts | C15: =Cashflow!C8 | D15: =Cashflow!D8 | E15: =Cashflow!E8 | F15: =Cashflow!F8 | G15: =Cashflow!G8 | H15: =SUM(C15:G15)
C16: =IFERROR(C15/C8,0) | D16: =IFERROR(D15/D8,0) | E16: =IFERROR(E15/E8,0) | F16: =IFERROR(F15/F8,0) | G16: =IFERROR(G15/G8,0) | H16: =IFERROR(H15/H8,0)
B17: Commission | C17: =Cashflow!C11 | D17: =Cashflow!D11 | E17: =Cashflow!E11 | F17: =Cashflow!F11 | G17: =Cashflow!G11 | H17: =SUM(C17:G17)
B18: (Calculated on Sales + GST) | C18: =IFERROR(C17/C8,0) | D18: =IFERROR(D17/D8,0) | E18: =IFERROR(E17/E8,0) | F18: =IFERROR(F17/F8,0) | G18: =IFERROR(G17/G8,0) | H18: =IFERROR(H17/H8,0)
B19: Marketing & Ads | C19: =Cashflow!C16 | D19: =Cashflow!D16 | E19: =Cashflow!E16 | F19: =Cashflow!F16 | G19: =Cashflow!G16 | H19: =SUM(C19:G19)
C20: =IFERROR(C19/C8,0) | D20: =IFERROR(D19/D8,0) | E20: =IFERROR(E19/E8,0) | F20: =IFERROR(F19/F8,0) | G20: =IFERROR(G19/G8,0) | H20: =IFERROR(H19/H8,0)
B21: Other charges & Tax Adjustments | C21: =Cashflow!C20+Cashflow!C26 | D21: =Cashflow!D20+Cashflow!D26 | E21: =Cashflow!E20+Cashflow!E26 | F21: =Cashflow!F20+Cashflow!F26 | G21: =Cashflow!G20+Cashflow!G26 | H21: =SUM(C21:G21)
C22: =IFERROR(C21/C8,0) | D22: =IFERROR(D21/D8,0) | E22: =IFERROR(E21/E8,0) | F22: =IFERROR(F21/F8,0) | G22: =IFERROR(G21/G8,0) | H22: =IFERROR(H21/H8,0)
B24: Money received | C24: =C8-C14-C17-C19-C21 | D24: =D8-D14-D17-D19-D21 | E24: =E8-E14-E17-E19-E21 | F24: =F8-F14-F17-F19-F21 | G24: =G8-G14-G17-G19-G21 | H24: =H8-H14-H17-H19-H21
C25: =IFERROR(C24/$C$8,0) | D25: =IFERROR(D24/$D$8,0) | E25: =IFERROR(E24/$E$8,0) | F25: =IFERROR(F24/$F$8,0) | G25: =IFERROR(G24/$G$8,0) | H25: =IFERROR(H24/$G$8,0)

Sheet Cashflow
A1: =Summary!B1 | K1: =H10+H8-H29 | M1: =H12*100/118
A2: Swiggy Cash Flow Statement - July 2025 | M2: =M1*0.02%
A4: S.No | B4: Details | C4: =Summary!C4 | D4: =Summary!D4 | E4: =Summary!E4 | F4: =Summary!F4 | G4: 27th to 31st | H4: Total
A5: 1 | B5: Item sales (Delivered orders) | C5: ='D1W1'!I2 | D5: ='D1W2'!I2 | E5: ='D1W3'!I2 | F5: ='D1W4'!I2 | H5: =SUM(C5:G5)
B6: Add:- Packing charges | C6: ='D1W1'!J2 | D6: ='D1W2'!J2 | E6: ='D1W3'!J2 | F6: ='D1W4'!J2 | H6: =SUM(C6:G6) | J6: GST | K6: =H10-H29
B7: Add:- Compensation paid for cancelled orders | C7: ='D1W1'!P1-'D1W1'!AG1 | D7: ='D1W2'!P1-'D1W2'!AG1 | E7: ='D1W3'!P1-'D1W3'!AG1 | F7: ='D1W4'!P1-'D1W4'!AG1 | H7: =SUM(C7:G7) | J7: TDS | K7: =H12*100/118
B8: Less:- Discount | C8: ='D1W1'!K2+'D1W1'!L2 | D8: ='D1W2'!K2+'D1W2'!L2 | E8: ='D1W3'!K2+'D1W3'!L2 | F8: ='D1W4'!K2+'D1W4'!L2 | H8: =SUM(C8:G8)
B9: Add:- GST 5% | C9: ='D1W1'!O2 | D9: ='D1W2'!O2 | E9: ='D1W3'!O2 | F9: ='D1W4'!O2 | H9: =SUM(C9:G9) | N9: =AVERAGE(J12:L12)
B10: Net Sales | C10: =C5+C6+C7-C8+C9 | D10: =D5+D6+D7-D8+D9 | E10: =E5+E6+E7-E8+E9 | F10: =F5+F6+F7-F8+F9 | G10: =G5+G6+G7-G8+G9 | H10: =SUM(C10:G10) | J10: =H10-H29
A11: 2 | B11: Less:- Commission | C11: =SUM(C12) | D11: =SUM(D12) | E11: =SUM(E12) | F11: =SUM(F12) | G11: =SUM(G12) | H11: =SUM(C11:G11)
B12: Platform Fee | C12: ='D1W1'!S3 | D12: ='D1W2'!S3 | E12: ='D1W3'!S3 | F12: ='D1W4'!S3 | H12: =SUM(C12:G12) | J12: =C12/C10 | K12: =D12/D10 | L12: =E12/E10 | M12: =F12/F10 | N12: =AVERAGE(J12:M12)
A13: 3 | B13: Less:- Refunds | C13: =SUM(C14:C15) | D13: =SUM(D14:D15) | E13: =(E14+E15) | F13: =(F14+F15) | G13: =(G14+G15) | H13: =SUM(C13:G13)
B14: Paid by Restaurant | C14: ='D1W1'!AF4 | D14: ='D1W2'!AF4 | E14: ='D1W3'!AF4 | F14: ='D1W4'!AF4 | H14: =SUM(C14:G14)
B15: Received by Restaurant | C15: 0 | D15: 0 | E15: 0 | F15: 0 | G15: 0 | H15: =SUM(C15:G15) | J15: =C10+C8-C29 | K15: =D10+D8-D29 | L15: =E10+E8-E29 | M15: =F10+F8-F29 | N15: =G10+G8-G29
A16: 4 | B16: Less:- Marketing Charges | C16: =SUM(C17:C19) | D16: =SUM(D17:D19) | E16: =E17+E18+E19 | F16: =F17+F18+F19 | G16: =G17+G18+G19 | H16: =SUM(C16:G16) | J16: =C12*100/118 | K16: =D12*100/118 | L16: =E12*100/118 | M16: =F12*100/118 | N16: =G12*100/118
B17: High Priority | C17: =-'D2W1'!B7 | D17: =-'D2W2'!B9 | E17: =-'D2W3'!B9 | F17: =-'D2W4'!B9 | H17: =SUM(C17:G17) | J17: =J16*2% | K17: =K16*2% | L17: =L16*2% | M17: =M16*2% | N17: =N16*2%
B18: Call Center Service Fees | C18: ='D1W1'!Z3 | D18: ='D1W2'!Z3 | E18: ='D1W3'!Z3 | F18: ='D1W4'!Z3 | H18: =SUM(C18:G18)
B19: PocketHero Fee | C19: ='D1W1'!V3 | D19: ='D1W2'!V3 | E19: ='D1W3'!V3 | F19: ='D1W4'!V3 | H19: =SUM(C19:G19)
A20: 5 | B20: Less:- Other Charges | C20: =SUM(C21:C24) | D20: =SUM(D21:D24) | E20: =SUM(E21:E24) | F20: =SUM(F21:F24) | G20: =SUM(G21:G24) | H20: =SUM(C20:G20)
B21: Collection Charges | C21: ='D1W1'!X3 | D21: ='D1W2'!X3 | E21: ='D1W3'!X3 | F21: ='D1W4'!X3 | H21: =SUM(C21:G21)
B22: Long Distance Fee | C22: ='D1W1'!T3 | D22: ='D1W2'!T3 | E22: ='D1W3'!T3 | F22: ='D1W4'!T3 | H22: =SUM(C22:G22)
B23: Swiggy One Fees | C23: ='D1W1'!W3 | D23: ='D1W2'!W3 | E23: ='D1W3'!W3 | F23: ='D1W4'!W3 | H23: =SUM(C23:G23)
B24: Merchant Cancellation Charges | C24: ='D1W1'!Y3 | D24: ='D1W2'!Y3 | E24: ='D1W3'!Y3 | F24: ='D1W4'!Y3 | H24: =SUM(C24:G24)
B25: Profit from Swiggy | C25: =C5+C6+C7-C8+C9-C12-C13-C16-C20-C29 | D25: =D5+D6+D7-D8+D9-D12-D13-D16-D20-D29 | E25: =E5+E6+E7-E8+E9-E12-E13-E16-E20-E29 | F25: =F5+F6+F7-F8+F9-F12-F13-F16-F20-F29 | G25: =G5+G6+G7-G8+G9-G12-G13-G16-G20-G29 | H25: =SUM(C25:G25) | N25: 259885
A26: 6 | B26: Less:- Tax Adjustments | C26: =SUM(C27:C29) | D26: =SUM(D27:D29) | E26: =SUM(E27:E29) | F26: =SUM(F27:F29) | G26: =SUM(G27:G29) | H26: =SUM(C26:G26) | N26: 9643
B27: TDS deduction for aggrigators | C27: ='D1W1'!AJ4 | D27: ='D1W2'!AJ4 | E27: ='D1W3'!AJ4 | F27: ='D1W4'!AJ4 | H27: =SUM(C27:G27)
B28: TCS | C28: ='D1W1'!AI4 | D28: ='D1W2'!AI4 | E28: ='D1W3'!AI4 | F28: ='D1W4'!AI4 | H28: =SUM(C28:G28) | N28: -23947.45
B29: GST collected and paid by swiggy | C29: ='D1W1'!AH4 | D29: ='D1W2'!AH4 | E29: ='D1W3'!AH4 | F29: ='D1W4'!AH4 | H29: =SUM(C29:G29) | N29: 12289.68
A30: 7 | B30: Expected Receipts | C30: =C25-C27 | D30: =D25-D27 | E30: =E25-E27 | F30: =F25-F27 | G30: =G25-G27 | H30: =SUM(C30:G30)
B31: Intriem payments | C31: 0 | D31: 0 | E31: 0 | F31: 0 | G31: 0 | H31: 0
B32: EMI Loan deductions | C32: 0 | D32: 0 | E32: 0 | F32: 0 | G32: 0 | H32: =SUM(C32:G32)
B33: Actual receipts | G33: =BANK!G2 | H33: =SUM(C33:G33)
A34: 8 | B34: Difference | C34: =C30-C31-C32-C33 | D34: =D30-D31-D32-D33 | E34: =E30-E31-E32-E33 | F34: =F30-F31-F32-F33 | G34: =G30-G31-G32-G33 | H34: =SUM(C34:G34)
B36: Notes:-
B37: 1. Last week bank credits will be credited in the next month.

Sheet BANK
C1: 1 | D1: 2 | E1: 3 | F1: 4 | G1: 5
B2: swiggy | C2: 21505.95 | D2: 30781.79 | E2: 30342.24 | F2: 38669.62
A10: Date | B10: Narration | C10: Chq./Ref.No. | D10: Value Dt | E10: Withdrawal Amt. | F10: Deposit Amt. | G10: Closing Balance
A11: 01/07/25 | B11: NEFT CR-YESB0000001-ONE 97 COMMUNICATIONS LIMITED SETTL-ROCKTAIL HOSPITALITY SERVICES-YESBN12025070104207251 | C11: YESBN12025070104207251 | D11: 01/07/25 | F11: 27641 | G11: 575581.24
A12: 01/07/25 | B12: NEFT CR-RATN0000999-PINELABS PVT LTD-ROCKTAIL HOSPITALITY SERVICES-RATNN52025070127611676 | C12: RATNN52025070127611676 | D12: 01/07/25 | F12: 1509.75 | G12: 577090.99
A13: 01/07/25 | B13: 42552392TERMINAL 1 CARDS SETTL. 01/07/25 | C13: 000000000000000 | D13: 01/07/25 | F13: 2521.73 | G13: 579612.72
A14: 01/07/25 | B14: GST/BANK REFERENCE NO: R2518264868104/CIN NO: HDFC25073600001570 | C14: 0250701360001319 | D14: 01/07/25 | E14: 108078 | G14: 471534.72
A15: 01/07/25 | B15: NEFT CR-YESB0000001-SWIGGY LIMITED-ROCKTAIL HOSPITALITY SERVICES-YESBN12025070105744412 | C15: YESBN12025070105744412 | D15: 01/07/25 | F15: 70187.2 | G15: 541721.92
A16: 02/07/25 | B16: NEFT CR-YESB0000001-ONE 97 COMMUNICATIONS LIMITED SETTL-ROCKTAIL HOSPITALITY SERVICES-YESBN12025070202489683 | C16: YESBN12025070202489683 | D16: 02/07/25 | F16: 32140.42 | G16: 573862.34
A17: 02/07/25 | B17: 42552392TERMINAL 1 CARDS SETTL. 02/07/25 | C17: 000000000000000 | D17: 02/07/25 | F17: 2252.65 | G17: 576114.99
A18: 02/07/25 | B18: 42552394TERMINAL 1 CARDS SETTL. 02/07/25 | C18: 000000000000000 | D18: 02/07/25 | F18: 556.76 | G18: 576671.75
A19: 02/07/25 | B19: NEFT CR-CITI0000002-ETERNAL LIMITED-ROCKTAIL HOSPITALITY SERVICES-CITIN52025070288932874 | C19: CITIN52025070288932874 | D19: 02/07/25 | F19: 47888.79 | G19: 624560.54
A20: 02/07/25 | B20: UPI-AGROMECH INDUSTRIES-BAJAJPAY.6879729.02771144@INDUS-INDB0MERCHA-107417334493-DOSA EQUIPMENT ADV | C20: 0000107417334493 | D20: 02/07/25 | E20: 30000 | G20: 594560.54
A21: 03/07/25 | B21: NEFT CR-YESB0000001-ONE 97 COMMUNICATIONS LIMITED SETTL-ROCKTAIL HOSPITALITY SERVICES-YESBN12025070301800334 | C21: YESBN12025070301800334 | D21: 03/07/25 | F21: 20179.42 | G21: 614739.96
A22: 03/07/25 | B22: 42552392TERMINAL 1 CARDS SETTL. 03/07/25 | C22: 000000000000000 | D22: 03/07/25 | F22: 8653.95 | G22: 623393.91
A23: 04/07/25 | B23: NEFT CR-YESB0000001-ONE 97 COMMUNICATIONS LIMITED SETTL-ROCKTAIL HOSPITALITY SERVICES-YESBN12025070403786865 | C23: YESBN12025070403786865 | D23: 04/07/25 | F23: 31048.13 | G23: 654442.04
A24: 04/07/25 | B24: 42552394TERMINAL 1 CARDS SETTL. 04/07/25 | C24: 000000000000000 | D24: 04/07/25 | F24: 4251.24 | G24: 658693.28
A25: 04/07/25 | B25: NEFT CR-YESB0000001-SWIGGY LIMITED-ROCKTAIL HOSPITALITY SERVICES-YESBN12025070405363208 | C25: YESBN12025070405363208 | D25: 04/07/25 | F25: 21022.24 | G25: 679715.52
A26: 04/07/25 | B26: NEFT CR-UTIB0000052-BUNDL TECHNOLOGIES PRIVATE LIMITED-ROCKTAIL HOSPITALITY SERVICES-UTIBN62025070410121377 | C26: UTIBN62025070410121377 | D26: 04/07/25 | F26: 46137.34 | G26: 725852.86
A27: 04/07/25 | B27: UPI-ZOMATO ONLINE ORDER-ZOMATOONLINEORD384743.RZP@RXAIRTEL-AIRP0000011-107550400754-ZOMATOONLINEORDER | C27: 0000107550400754 | D27: 04/07/25 | E27: 2589.1 | G27: 723263.76
A28: 04/07/25 | B28: UPI-ZOMATO ONLINE ORDER-ZOMATOONLINEORD384743.RZP@RXAIRTEL-AIRP0000011-107550521516-ZOMATOONLINEORDER | C28: 0000107550521516 | D28: 05/07/25 | E28: 2589.1 | G28: 720674.66
A29: 05/07/25 | B29: NEFT CR-YESB0000001-ONE 97 COMMUNICATIONS LIMITED SETTL-ROCKTAIL HOSPITALITY SERVICES-YESBN12025070503391886 | C29: YESBN12025070503391886 | D29: 05/07/25 | F29: 53539.04 | G29: 774213.7
A30: 05/07/25 | B30: 42552392TERMINAL 1 CARDS SETTL. 05/07/25 | C30: 000000000000000 | D30: 05/07/25 | F30: 3251.71 | G30: 777465.41
A31: 05/07/25 | B31: SETTLEMENT CHARGE-JUN25-CPY594 | C31: 000000000000000 | D31: 05/07/25 | E31: 30.68 | G31: 777434.73
A32: 05/07/25 | B32: SETTLEMENT CHARGE-JUN25-CPY597 | C32: 000000000000000 | D32: 05/07/25 | E32: 25.96 | G32: 777408.77
A33: 06/07/25 | B33: NEFT CR-YESB0000001-ONE 97 COMMUNICATIONS LIMITED SETTL-ROCKTAIL HOSPITALITY SERVICES-YESBN12025070603478046 | C33: YESBN12025070603478046 | D33: 06/07/25 | F33: 79401.62 | G33: 856810.39
A34: 06/07/25 | B34: EMI 162047443 CHQ S16204744311 0725162047443 | C34: 000000000000000 | D34: 06/07/25 | E34: 70666 | G34: 786144.39
A35: 06/07/25 | B35: 42552392TERMINAL 1 CARDS SETTL. 06/07/25 | C35: 000000000000000 | D35: 06/07/25 | F35: 7572.79 | G35: 793717.18
A36: 06/07/25 | B36: 42552394TERMINAL 1 CARDS SETTL. 06/07/25 | C36: 000000000000000 | D36: 06/07/25 | F36: 10604.11 | G36: 804321.29
A37: 06/07/25 | B37: UPI-WOLFFPACK VENTURES P-ABHISHEK.LADHA11-1@OKHDFCBANK-HDFC0000512-107618941469-LOAN EMI | C37: 0000107618941469 | D37: 06/07/25 | F37: 35333 | G37: 839654.29
A38: 06/07/25 | B38: UPI-HARISH RAGHAVENDRA-HARISH.RAGHAVENDRA26@OKHDFCBANK-ICIC0000069-245979904572-PIZZA STONE | C38: 0000245979904572 | D38: 06/07/25 | E38: 10000 | G38: 829654.29
A39: 06/07/25 | B39: UPI-RAZORPAY-PG.RAZORPAY@AXISBANK-UTIB0001506-321362241875-ZOMATOOREFUNDQP553 | C39: 0000321362241875 | D39: 06/07/25 | F39: 2589.1 | G39: 832243.39
A40: 07/07/25 | B40: NEFT CR-YESB0000001-ONE 97 COMMUNICATIONS LIMITED SETTL-ROCKTAIL HOSPITALITY SERVICES-YESBN12025070703506891 | C40: YESBN12025070703506891 | D40: 07/07/25 | F40: 68500.38 | G40: 900743.77
A41: 07/07/25 | B41: 42552392TERMINAL 1 CARDS SETTL. 07/07/25 | C41: 000000000000000 | D41: 07/07/25 | F41: 6448.08 | G41: 907191.85
A42: 07/07/25 | B42: 42552394TERMINAL 1 CARDS SETTL. 07/07/25 | C42: 000000000000000 | D42: 07/07/25 | F42: 6613.36 | G42: 913805.21
A43: 07/07/25 | B43: NEFT CR-CITI0000002-ETERNAL LIMITED-ROCKTAIL HOSPITALITY SERVICES-CITIN52025070790533046 | C43: CITIN52025070790533046 | D43: 07/07/25 | F43: 54165.64 | G43: 967970.85
A44: 07/07/25 | B44: UPI-GADDAM NIRANJAN-G.NIRANJANNANI-1@OKAXIS-UTIB0000027-107702908442-UPI | C44: 0000107702908442 | D44: 07/07/25 | E44: 500 | G44: 967470.85
A45: 08/07/25 | B45: NEFT CR-YESB0000001-ONE 97 COMMUNICATIONS LIMITED SETTL-ROCKTAIL HOSPITALITY SERVICES-YESBN12025070802852556 | C45: YESBN12025070802852556 | D45: 08/07/25 | F45: 29438 | G45: 996908.85
A46: 08/07/25 | B46: NEFT CR-SCBL0036001-AMERICAN EXPRESS BANKING CORP-ROCKTAIL HOSPITALITY SERVICES-SCBLN52025070800525663 | C46: SCBLN52025070800525663 | D46: 08/07/25 | F46: 968.25 | G46: 997877.1
A47: 08/07/25 | B47: 42552394TERMINAL 1 CARDS SETTL. 08/07/25 | C47: 000000000000000 | D47: 08/07/25 | F47: 5211.01 | G47: 1003088.1
...

Sheet Profit statement
B1: =Summary!B1
B2: Swiggy Profit Statement - July 2025
B4: Details | C4: =Cashflow!C4 | D4: =Cashflow!D4 | E4: =Cashflow!E4 | F4: =Cashflow!F4 | G4: =Summary!G4 | H4: Total
B5: A. Net Sales
B6: Total Income | C6: =Cashflow!C5+Cashflow!C6-Cashflow!C8+Cashflow!C9-Cashflow!C29 | D6: =Cashflow!D5+Cashflow!D6-Cashflow!D8+Cashflow!D9-Cashflow!D29 | E6: =Cashflow!E5+Cashflow!E6-Cashflow!E8+Cashflow!E9-Cashflow!E29 | F6: =Cashflow!F5+Cashflow!F6-Cashflow!F8+Cashflow!F9-Cashflow!F29 | G6: =Cashflow!G5+Cashflow!G6-Cashflow!G8+Cashflow!G9-Cashflow!G29 | H6: =SUM(C6:G6)
B7: Add- Adjust: Cancelled orders (By Swiggy) | C7: =Cashflow!C7 | D7: 0 | E7: =Cashflow!E7 | F7: =Cashflow!F7 | G7: =Cashflow!G7 | H7: =SUM(C7:G7)
B8: Net Sales (Number that you see on Numerize app) | C8: =C6+C7 | D8: =D6+D7 | E8: =E6+E7 | F8: =F6+F7 | G8: =G6+G7 | H8: =H6+H7
B10: B. Less:- Commission | C10: =Cashflow!C11 | D10: =Cashflow!D11 | E10: =Cashflow!E11 | F10: =Cashflow!F11 | G10: =Cashflow!G11 | H10: =SUM(C10:G10)
B12: C. Less:- Marketing & Ads | C12: =Cashflow!C16 | D12: =Cashflow!D16 | E12: =Cashflow!E16 | F12: =Cashflow!F16 | G12: =Cashflow!G16 | H12: =SUM(C12:G12)
B14: D. Less:- Refund on disputed orders | C14: =Cashflow!C13 | D14: =Cashflow!D13 | E14: =Cashflow!E13 | F14: =Cashflow!F13 | G14: =Cashflow!G13 | H14: =SUM(C14:G14)
B16: E. Other charges | C16: =Cashflow!C20 | D16: =Cashflow!D20 | E16: =Cashflow!E20 | F16: =Cashflow!F20 | G16: =Cashflow!G20 | H16: =SUM(C16:G16)
B18: F. Profit | C18: =C8-C10-C12-C14-C16 | D18: =D8-D10-D12-D14-D16 | E18: =E8-E10-E12-E14-E16 | F18: =F8-F10-F12-F14-F16 | G18: =G8-G10-G12-G14-G16 | H18: =H8-H10-H12-H14-H16
B19: Percentage | C19: =C18/C8 | D19: =D18/D8 | E19: =IFERROR(E18/E8,0) | F19: =IFERROR(F18/F8,0) | G19: =IFERROR(G18/G8,0) | H19: =H18/H8

Sheet Discrepancies
B1: =Summary!B1
B2: Swiggy Discrepancies - July 2025
B4: Details | C4: =Summary!C4 | D4: =Summary!D4 | E4: =Summary!E4 | F4: =Summary!F4 | G4: =Summary!G4 | H4: Total
B5: A. POS discrepancies
B6: Sales as per Swiggy | C6: =Cashflow!C10 | D6: =Cashflow!D10 | E6: =Cashflow!E10 | F6: =Cashflow!F10 | G6: =Cashflow!G10 | H6: =SUM(C6:G6)
B7: Sale as per POS | H7: =SUM(C7:G7)
B8: Difference | C8: =C6-C7 | D8: =D6-D7 | E8: =E6-E7 | F8: =F6-F7 | G8: =G6-G7 | H8: =SUM(C8:G8)
C9: =IFERROR(C8/C6,0) | D9: =IFERROR(D8/D6,0) | E9: =IFERROR(E8/E6,0) | F9: =IFERROR(F8/F6,0) | G9: =IFERROR(G8/G6,0) | H9: =IFERROR(H8/H6,0)
B11: B. Order discrepancies
B12: No.of delivered orders for which payment isn't received | C12: 0 | D12: 0 | E12: 0 | F12: 0 | G12: 0 | H12: =SUM(C12:G12)
B13: Value of such orders | C13: 0 | D13: 0 | E13: 0 | F13: 0 | G13: 0 | H13: =SUM(C13:G13)
B16: C. Payment discrepancies
B17: Expected receipts in the bank account | C17: =Cashflow!C30 | D17: =Cashflow!D30 | E17: =Cashflow!E30 | F17: =Cashflow!F30 | G17: =Cashflow!G30 | H17: =SUM(C17:G17)
B18: Interim Payments | C18: 0 | D18: 0 | E18: 0 | F18: 0 | G18: 0 | H18: =SUM(C18:G18)
B19: Actual receipts in the bank | H19: =SUM(C19:G19)
B20: Difference | C20: =C17-C19-C18 | D20: =D17-D19-D18 | E20: =E17-E19-E18 | F20: =F17-F19-F18 | G20: =G17-G19-G18 | H20: =H17-H19-H18
B22: Notes:
B23: 1. Last week bank credits will be credited in the next month.
B24: 2. There is difference between POS and actual sales, 208.43/- is less in POS

Sheet POS
G1: Week 1 | H1: Week 2 | I1: Week 3 | J1: Week 4 | K1: Week 5
G2: 34088 | H2: 46933 | I2: 48536 | J2: 62572 | K2: 31390
N8: {=SUBTOTAL(9,N10:N2235)}
A9: Invoice No. | B9: Date | C9: Payment Type | D9: Order Type | E9: Status | F9: Persons | G9: Area | H9: Assign To | I9: Cash | J9: Card | K9: Due Payment | L9: Other | M9: Wallet | N9: Online
A10: 86857 | B10: 45870 | C10: Cash | D10: Dine In | E10: Success | G10: Dine in | H10: Pavan | I10: 372 | J10: 0 | K10: 0 | L10: 0 | M10: 0 | N10: 0
A11: 86856 | B11: 45870 | C11: Other [Swiggy Dineout] | D11: Dine In | E11: Success | G11: Dine in | H11: Pavan | I11: 0 | J11: 0 | K11: 0 | L11: 2105 | M11: 0 | N11: 0
A12: 86855 | B12: 45870 | C12: Cash | D12: Dine In | E12: Success | F12: 2 | G12: Dine in | H12: Prashant | I12: 1009 | J12: 0 | K12: 0 | L12: 0 | M12: 0 | N12: 0
A13: 86854 | B13: 45870 | C13: Other [upi] | D13: Dine In | E13: Success | F13: 3 | G13: Dine in | H13: Prashant | I13: 0 | J13: 0 | K13: 0 | L13: 1678 | M13: 0 | N13: 0
A14: 86853 | B14: 45870 | C14: Other [upi] | D14: Dine In | E14: Success | G14: Dine in | H14: Pavan | I14: 0 | J14: 0 | K14: 0 | L14: 2272 | M14: 0 | N14: 0
A15: 86852 | B15: 45870 | C15: CARD | D15: Dine In | E15: Success | G15: Dine in | H15: Prashant | I15: 0 | J15: 1010 | K15: 0 | L15: 0 | M15: 0 | N15: 0
A16: 86851 | B16: 45870 | C16: Other [Swiggy Dineout] | D16: Dine In | E16: Success | F16: 3 | G16: Dine in | H16: Prashant | I16: 0 | J16: 0 | K16: 0 | L16: 1844 | M16: 0 | N16: 0
A17: 86850 | B17: 45870 | C17: Other [upi] | D17: Dine In | E17: Success | G17: Dine in | H17: Pavan | I17: 0 | J17: 0 | K17: 0 | L17: 120 | M17: 0 | N17: 0
A18: 86849 | B18: 45870 | C18: Other [Zomato Gold] | D18: Dine In | E18: Success | F18: 3 | G18: Dine in | H18: Pavan | I18: 0 | J18: 0 | K18: 0 | L18: 2687 | M18: 0 | N18: 0
A19: 86848 | B19: 45870 | C19: Other [Swiggy Dineout] | D19: Dine In | E19: Success | F19: 2 | G19: Dine in | H19: Prashant | I19: 0 | J19: 0 | K19: 0 | L19: 1525 | M19: 0 | N19: 0
A20: 86847 | B20: 45870 | C20: Other [upi] | D20: Dine In | E20: Success | G20: Dine in | H20: Prashant | I20: 0 | J20: 0 | K20: 0 | L20: 460 | M20: 0 | N20: 0
A21: 86846 | B21: 45870 | C21: Other [Zomato Gold] | D21: Dine In | E21: Success | G21: Dine in | H21: Pavan | I21: 0 | J21: 0 | K21: 0 | L21: 987 | M21: 0 | N21: 0
A22: 86845 | B22: 45870 | C22: Other [upi] | D22: Dine In | E22: Success | G22: Dine in | H22: Pavan | I22: 0 | J22: 0 | K22: 0 | L22: 307 | M22: 0 | N22: 0
A23: 86844 | B23: 45870 | C23: Other [Swiggy Dineout] | D23: Dine In | E23: Success | G23: Dine in | I23: 0 | J23: 0 | K23: 0 | L23: 2830 | M23: 0 | N23: 0
A24: 86843 | B24: 45870 | C24: Other [Zomato Gold] | D24: Dine In | E24: Success | F24: 4 | G24: Dine in | H24: Prashant | I24: 0 | J24: 0 | K24: 0 | L24: 2840 | M24: 0 | N24: 0
A25: 86842 | B25: 45870 | C25: Other [Zomato Gold] | D25: Dine In | E25: Success | G25: Dine in | H25: Prashant | I25: 0 | J25: 0 | K25: 0 | L25: 1535 | M25: 0 | N25: 0
A26: 86841 | B26: 45870 | C26: Other [Zomato Gold] | D26: Dine In | E26: Success | F26: 3 | G26: Dine in | H26: Prashant | I26: 0 | J26: 0 | K26: 0 | L26: 2390 | M26: 0 | N26: 0
A27: 86840 | B27: 45870 | C27: CARD | D27: Dine In | E27: Success | G27: Dine in | H27: This is It | I27: 0 | J27: 1547 | K27: 0 | L27: 0 | M27: 0 | N27: 0
A28: 86839 | B28: 45870 | C28: Other [Zomato Gold] | D28: Dine In | E28: Success | G28: Dine in | H28: Pavan | I28: 0 | J28: 0 | K28: 0 | L28: 1062 | M28: 0 | N28: 0
A29: 86838 | B29: 45870 | C29: Online | D29: Delivery(Parcel) | E29: Success | G29: Zomato | I29: 0 | J29: 0 | K29: 0 | L29: 0 | M29: 0 | N29: 784
A30: 86837 | B30: 45870 | C30: Other [upi] | D30: Dine In | E30: Success | G30: Dine in | H30: Prashant | I30: 0 | J30: 0 | K30: 0 | L30: 920 | M30: 0 | N30: 0
A31: 86836 | B31: 45870 | C31: Other [upi] | D31: Dine In | E31: Success | F31: 3 | G31: Dine in | H31: Prashant | I31: 0 | J31: 0 | K31: 0 | L31: 1064 | M31: 0 | N31: 0
A32: 86835 | B32: 45870 | C32: Online | D32: Delivery(Parcel) | E32: Success | G32: Swiggy_This is it Cafe | I32: 0 | J32: 0 | K32: 0 | L32: 0 | M32: 0 | N32: 403
A33: 86834 | B33: 45870 | C33: Other [upi] | D33: Dine In | E33: Success | F33: 4 | G33: Dine in | H33: Prashant | I33: 0 | J33: 0 | K33: 0 | L33: 1591 | M33: 0 | N33: 0
A34: 86833 | B34: 45870 | C34: Online | D34: Delivery(Parcel) | E34: Success | G34: Zomato | I34: 0 | J34: 0 | K34: 0 | L34: 0 | M34: 0 | N34: 980
A35: 86832 | B35: 45870 | C35: Online | D35: Delivery(Parcel) | E35: Success | G35: Zomato | I35: 0 | J35: 0 | K35: 0 | L35: 0 | M35: 0 | N35: 188
A36: 86831 | B36: 45870 | C36: Other [Swiggy Dineout] | D36: Dine In | E36: Success | G36: Dine in | H36: Pavan | I36: 0 | J36: 0 | K36: 0 | L36: 1393 | M36: 0 | N36: 0
A37: 86830 | B37: 45870 | C37: Other [upi] | D37: Dine In | E37: Success | G37: Dine in | H37: Pavan | I37: 0 | J37: 0 | K37: 0 | L37: 438 | M37: 0 | N37: 0
A38: 86829 | B38: 45870 | C38: CARD | D38: Dine In | E38: Success | F38: 2 | G38: Dine in | H38: Prashant | I38: 0 | J38: 2460 | K38: 0 | L38: 0 | M38: 0 | N38: 0
A39: 86828 | B39: 45870 | C39: Cash | D39: Dine In | E39: Success | G39: Dine in | H39: Pavan | I39: 900 | J39: 0 | K39: 0 | L39: 0 | M39: 0 | N39: 0
A40: 86827 | B40: 45870 | C40: Online | D40: Delivery(Parcel) | E40: Success | G40: Zomato | I40: 0 | J40: 0 | K40: 0 | L40: 0 | M40: 0 | N40: 775
A41: 86826 | B41: 45870 | C41: Other [upi] | D41: Dine In | E41: Success | G41: Dine in | H41: Pavan | I41: 0 | J41: 0 | K41: 0 | L41: 274 | M41: 0 | N41: 0
A42: 86825 | B42: 45870 | C42: Other [Zomato Gold] | D42: Dine In | E42: Success | G42: Dine in | H42: Pavan | I42: 0 | J42: 0 | K42: 0 | L42: 1393 | M42: 0 | N42: 0
A43: 86824 | B43: 45870 | C43: Other [upi] | D43: Dine In | E43: Success | G43: Dine in | H43: This is It | I43: 0 | J43: 0 | K43: 0 | L43: 669 | M43: 0 | N43: 0
A44: 86823 | B44: 45870 | C44: Online | D44: Delivery(Parcel) | E44: Success | G44: Zomato | I44: 0 | J44: 0 | K44: 0 | L44: 0 | M44: 0 | N44: 701
A45: 86822 | B45: 45870 | C45: Other [upi] | D45: Dine In | E45: Success | G45: Dine in | H45: Pavan | I45: 0 | J45: 0 | K45: 0 | L45: 723 | M45: 0 | N45: 0
...

Sheet D1W1
I1: 290 | J1: 10 | K1: 50 | L1: 0 | M1: 50 | N1: 250 | O1: 12.5 | P1: 262.5 | Q1: 262.5 | R1: 0 | S1: 57.75 | T1: 0 | U1: 0 | V1: 0 | W1: 0 | X1: 5.25 | Y1: 7.4 | Z1: 0 | AA1: 0 | AB1: 0 | AC1: 12.68 | AD1: 83.08 | AE1: 0 | AF1: 0 | AG1: 0 | AH1: 12.5 | AI1: 0 | AJ1: 0.25 | AK1: 12.75 | AL1: 166.68 | AM1: 0 | AN1: 22.192 | AO1: 0 | AP1: 0 | AQ1: 0 | AR1: 0 | AS1: 0 | AT1: 0 | AU1: 68.683333 | AV1: 0 | AW1: 0 | AX1: 0 | AY1: 0 | AZ1: 0 | BA1: 0 | BB1: 0 | BC1: 0 | BD1: 0 | BE1: 0 | BF1: 0 | BG1: 0 | BH1: 0 | BI1: 0 | BJ1: 0 | BK1: 0 | BL1: 0 | BM1: 0 | BN1: 0 | BO1: 0 | BP1: 0 | BQ1: 0 | BR1: 0 | BS1: 0 | BT1: 0 | BU1: 0 | BV1: 0 | BW1: 0 | BX1: 0 | BY1: 0 | BZ1: 0 | CA1: 0 | CB1: 0 | CC1: 0
I2: 5105 | J2: 205 | K2: 445.99 | L2: 0 | M2: 445.99 | N2: 4864.01 | O2: 243.24 | P2: 5107.25 | Q2: 5107.21 | R2: 0 | S2: 1123.58 | T2: 0 | U2: 0 | V2: 0 | W2: 18 | X2: 102.14 | Y2: 0 | Z2: 10 | AA2: 0 | AB2: 0 | AC2: 225.64 | AD2: 1479.36 | AE2: 0 | AF2: 0 | AG2: 0 | AH2: 243.2 | AI2: 0 | AJ2: 4.86 | AK2: 248.06 | AL2: 3379.77 | AM2: 0 | AN2: 48.746 | AO2: 0 | AP2: 0 | AQ2: 0 | AR2: 0 | AS2: 0 | AT2: 0 | AU2: 0 | AV2: 0 | AW2: 0 | AX2: 0 | AY2: 0 | AZ2: 0 | BA2: 0 | BB2: 0 | BC2: 0 | BD2: 0 | BE2: 0 | BF2: 0 | BG2: 0 | BH2: 0 | BI2: 0 | BJ2: 0 | BK2: 0 | BL2: 0 | BM2: 0 | BN2: 0 | BO2: 0 | BP2: 0 | BQ2: 0 | BR2: 0 | BS2: 0 | BT2: 0 | BU2: 0 | BV2: 0 | BW2: 0 | BX2: 0 | BY2: 0 | BZ2: 0 | CA2: 0 | CB2: 0 | CC2: 0
I3: 6366.1 | J3: 253.7 | K3: 585.2682 | L3: 0 | M3: 585.2682 | N3: 6034.5318 | O3: 301.7732 | P3: 6336.305 | Q3: 6336.2578 | R3: 0 | S3: 1393.9694 | T3: 0 | U3: 0 | V3: 0 | W3: 21.24 | X3: 126.7202 | Y3: 8.732 | Z3: 11.8 | AA3: 0 | AB3: 0 | AC3: 281.2176 | AD3: 1843.6792 | AE3: 0 | AF3: 0 | AG3: 0 | AH3: 301.726 | AI3: 0 | AJ3: 6.0298 | AK3: 307.7558 | AL3: 4184.811 | AM3: 0 | AN3: 83.70684 | AO3: 0 | AP3: 0 | AQ3: 0 | AR3: 0 | AS3: 0 | AT3: 0 | AU3: 81.046333 | AV3: 0 | AW3: 0 | AX3: 0 | AY3: 0 | AZ3: 0 | BA3: 0 | BB3: 0 | BC3: 0 | BD3: 0 | BE3: 0 | BF3: 0 | BG3: 0 | BH3: 0 | BI3: 0 | BJ3: 0 | BK3: 0 | BL3: 0 | BM3: 0 | BN3: 0 | BO3: 0 | BP3: 0 | BQ3: 0 | BR3: 0 | BS3: 0 | BT3: 0 | BU3: 0 | BV3: 0 | BW3: 0 | BX3: 0 | BY3: 0 | BZ3: 0 | CA3: 0 | CB3: 0 | CC3: 0
I4: 5395 | J4: 215 | K4: 495.99 | L4: 0 | M4: 495.99 | N4: 5114.01 | O4: 255.74 | P4: 5369.75 | Q4: 5369.71 | R4: 0 | S4: 1181.33 | T4: 0 | U4: 0 | V4: 0 | W4: 18 | X4: 107.39 | Y4: 7.4 | Z4: 10 | AA4: 0 | AB4: 0 | AC4: 238.32 | AD4: 1562.44 | AE4: 0 | AF4: 0 | AG4: 0 | AH4: 255.7 | AI4: 0 | AJ4: 5.11 | AK4: 260.81 | AL4: 3546.45 | AM4: 0 | AN4: 70.938 | AO4: 0 | AP4: 0 | AQ4: 0 | AR4: 0 | AS4: 0 | AT4: 0 | AU4: 68.683333 | AV4: 0 | AW4: 0 | AX4: 0 | AY4: 0 | AZ4: 0 | BA4: 0 | BB4: 0 | BC4: 0 | BD4: 0 | BE4: 0 | BF4: 0 | BG4: 0 | BH4: 0 | BI4: 0 | BJ4: 0 | BK4: 0 | BL4: 0 | BM4: 0 | BN4: 0 | BO4: 0 | BP4: 0 | BQ4: 0 | BR4: 0 | BS4: 0 | BT4: 0 | BU4: 0 | BV4: 0 | BW4: 0 | BX4: 0 | BY4: 0 | BZ4: 0 | CA4: 0 | CB4: 0 | CC4: 0
A5: Order ID | B5: Parent Order ID | C5: Order Date | D5: Order Status | E5: Order Category | F5: Order Payment Type | G5: Cancelled By? | H5: Coupon type applied by customer | I5: Item Total | J5: Packaging Charges | K5: Restaurant Discounts (Promo, Freebies, Flat Off, etc.) | L5: Swiggy One Exclusive Offer Discount | M5: Restaurant Discount Share [3a+3b] | N5: Net Bill Value (before taxes) [1+2-3] | O5: GST Collected | P5: Total Customer Paid [4+5] | Q5: Commission charged on | R5: Service Fees % | S5: Commission | T5: Long Distance Charges | U5: Discount on Long Distance Fee | V5: Pocket Hero Fees | W5: Swiggy One Fees | X5: Payment Collection Charges | Y5: Restaurant Cancellation Charges | Z5: Call Center Charges | AA5: Delivery Fee sponsored by Restaurant (w/o tax) | AB5: Bolt Fees | AC5: GST on Service Fee @18% | AD5: Total Swiggy Fees [6+7+8-9+10+11+12+13+14+15+16] | AE5: Customer Cancellations | AF5: Customer Complaints | AG5: Complaint & Cancellation Charges [17+18] | AH5: GST Deduction | AI5: TCS | AJ5: TDS | AK5: Total Taxes [19+20+21] | AL5: Net Payout for Order (after taxes) [A-B-C-D] | AM5: Long Distance Order | AN5: Last Mile (in km) | AO5: MFR Accurate? | AP5: MFR Pressed? | AQ5: Coupon Code Sourced | AR5: Discount Campaign ID | AS5: Replicated Order | AT5: Base order ID | AU5: Cancellation time | AV5: Pick Up Status | AW5: Swiggy One Customer? | AX5: Pocket Hero Order?
A6: 218311536832462 | C6: 2025-10-01 23:35:36 | D6: delivered | E6: regular | H6: SWIGGYIT | I6: 400 | J6: 15 | K6: 50 | L6: 0 | M6: 50 | N6: 365 | O6: 18.26 | P6: 383.26 | Q6: 383.24 | R6: 22.0% | S6: 84.31 | T6: 0 | U6: 0 | V6: 0 | W6: 0 | X6: 7.66 | Y6: 0 | Z6: 0 | AA6: 0 | AB6: 0 | AC6: 16.56 | AD6: 108.53 | AE6: 0 | AF6: 0 | AG6: 0 | AH6: 18.25 | AI6: 0 | AJ6: 0.36 | AK6: 18.61 | AL6: 256.12 | AM6: No | AN6: 4.519 | AO6: No | AP6: No | AR6: 109681730 | AS6: No | AW6: No | AX6: No
A7: 218313185419967 | C7: 2025-10-02 00:03:05 | D7: delivered | E7: regular | H7: FLAT100 | I7: 1030 | J7: 45 | K7: 99.99 | L7: 0 | M7: 99.99 | N7: 975.01 | O7: 48.76 | P7: 1023.77 | Q7: 1023.77 | R7: 22.0% | S7: 225.23 | T7: 0 | U7: 0 | V7: 0 | W7: 3 | X7: 20.48 | Y7: 0 | Z7: 0 | AA7: 0 | AB7: 0 | AC7: 44.76 | AD7: 293.47 | AE7: 0 | AF7: 0 | AG7: 0 | AH7: 48.75 | AI7: 0 | AJ7: 0.98 | AK7: 49.73 | AL7: 680.55 | AM7: No | AN7: 4.787 | AO7: No | AP7: No | AR7: 206500dc-ba9e-4a58-be62-bb3f830ec1f3,206500dc-ba9e-4a58-be62-bb3f830ec1f3 | AS7: No | AW7: Yes | AX7: No
A8: 218358408475705 | C8: 2025-10-02 12:36:48 | D8: cancelled | E8: regular | F8: prepaid | G8: MERCHANT | H8: TRYNEW | I8: 0 | J8: 0 | K8: 0 | L8: 0 | M8: 0 | N8: 0 | O8: 0 | P8: 0 | Q8: 0 | R8: 22.0% | S8: 0 | T8: 0 | U8: 0 | V8: 0 | W8: 0 | X8: 0 | Y8: 3.55 | Z8: 0 | AA8: 0 | AB8: 0 | AC8: 0.64 | AD8: 4.19 | AE8: 0 | AF8: 0 | AG8: 0 | AH8: 0 | AI8: 0 | AJ8: 0 | AK8: 0 | AL8: -4.19 | AM8: No | AN8: 7.358 | AO8: No | AP8: No | AS8: No | AU8: 16.583333 | AV8: not picked up | AW8: Yes | AX8: No
A9: 218381112148353 | C9: 2025-10-02 18:55:12 | D9: delivered | E9: regular | H9: SWIGGYIT | I9: 375 | J9: 15 | K9: 50 | L9: 0 | M9: 50 | N9: 340 | O9: 17 | P9: 357 | Q9: 357 | R9: 22.0% | S9: 78.54 | T9: 0 | U9: 0 | V9: 0 | W9: 3 | X9: 7.14 | Y9: 0 | Z9: 0 | AA9: 0 | AB9: 0 | AC9: 15.96 | AD9: 104.64 | AE9: 0 | AF9: 0 | AG9: 0 | AH9: 17 | AI9: 0 | AJ9: 0.34 | AK9: 17.34 | AL9: 235.02 | AM9: No | AN9: 2.907 | AO9: No | AP9: No | AR9: 39d32da7-47a1-4788-bf6b-1e869bb94cbb,206500dc-ba9e-4a58-be62-bb3f830ec1f3,39d32da7-47a1-4788-bf6b-1e869bb94cbb,206500dc-ba9e-4a58-be62-bb3f830ec1f3 | AS9: No | AW9: Yes | AX9: No
A10: 218386921333424 | C10: 2025-10-02 20:32:01 | D10: delivered | E10: regular | I10: 540 | J10: 20 | K10: 0 | L10: 0 | M10: 0 | N10: 560 | O10: 28 | P10: 588 | Q10: 588 | R10: 22.0% | S10: 129.36 | T10: 0 | U10: 0 | V10: 0 | W10: 0 | X10: 11.76 | Y10: 0 | Z10: 10 | AA10: 0 | AB10: 0 | AC10: 27.2 | AD10: 178.32 | AE10: 0 | AF10: 0 | AG10: 0 | AH10: 28 | AI10: 0 | AJ10: 0.56 | AK10: 28.56 | AL10: 381.12 | AM10: No | AN10: 1.961 | AO10: No | AP10: No | AS10: No | AW10: No | AX10: No
A11: 218390795782865 | C11: 2025-10-02 21:36:35 | D11: cancelled | E11: regular | F11: cash | G11: MERCHANT | H11: TRYNEW | I11: 0 | J11: 0 | K11: 0 | L11: 0 | M11: 0 | N11: 0 | O11: 0 | P11: 0 | Q11: 0 | R11: 22.0% | S11: 0 | T11: 0 | U11: 0 | V11: 0 | W11: 0 | X11: 0 | Y11: 3.85 | Z11: 0 | AA11: 0 | AB11: 0 | AC11: 0.7 | AD11: 4.55 | AE11: 0 | AF11: 0 | AG11: 0 | AH11: 0 | AI11: 0 | AJ11: 0 | AK11: 0 | AL11: -4.54 | AM11: No | AN11: 9.335 | AO11: No | AP11: No | AS11: No | AU11: 17.733333 | AV11: not picked up | AW11: Yes | AX11: No
A12: 218397634764449 | C12: 2025-10-02 23:30:34 | D12: delivered | E12: regular | I12: 230 | J12: 10 | K12: 0 | L12: 0 | M12: 0 | N12: 240 | O12: 12 | P12: 252 | Q12: 252 | R12: 22.0% | S12: 55.44 | T12: 0 | U12: 0 | V12: 0 | W12: 3 | X12: 5.04 | Y12: 0 | Z12: 0 | AA12: 0 | AB12: 0 | AC12: 11.42 | AD12: 74.9 | AE12: 0 | AF12: 0 | AG12: 0 | AH12: 12 | AI12: 0 | AJ12: 0.24 | AK12: 12.24 | AL12: 164.84 | AM12: No | AN12: 4.096 | AO12: No | AP12: No | AR12: 1d096f82-2042-42af-8b16-bfa6dc6bcc60,206500dc-ba9e-4a58-be62-bb3f830ec1f3 | AS12: No | AW12: Yes | AX12: No
A13: 218477439751637 | C13: 2025-10-03 21:40:39 | D13: delivered | E13: regular | H13: TRYNEW | I13: 460 | J13: 20 | K13: 50 | L13: 0 | M13: 50 | N13: 430 | O13: 21.5 | P13: 451.5 | Q13: 451.5 | R13: 22.0% | S13: 99.33 | T13: 0 | U13: 0 | V13: 0 | W13: 3 | X13: 9.03 | Y13: 0 | Z13: 0 | AA13: 0 | AB13: 0 | AC13: 20.04 | AD13: 131.4 | AE13: 0 | AF13: 0 | AG13: 0 | AH13: 21.5 | AI13: 0 | AJ13: 0.43 | AK13: 21.93 | AL13: 298.17 | AM13: No | AN13: 9.491 | AO13: No | AP13: No | AR13: 109681737 | AS13: No | AW13: Yes | AX13: No
A14: 218541165914385 | C14: 2025-10-04 15:22:45 | D14: delivered | E14: regular | H14: MISSEDYOU | I14: 230 | J14: 10 | K14: 46 | L14: 0 | M14: 46 | N14: 194 | O14: 9.7 | P14: 203.7 | Q14: 203.7 | R14: 22.0% | S14: 44.81 | T14: 0 | U14: 0 | V14: 0 | W14: 0 | X14: 4.07 | Y14: 0 | Z14: 0 | AA14: 0 | AB14: 0 | AC14: 8.8 | AD14: 57.68 | AE14: 0 | AF14: 0 | AG14: 0 | AH14: 9.7 | AI14: 0 | AJ14: 0.19 | AK14: 9.89 | AL14: 136.13 | AM14: No | AN14: 4.554 | AO14: No | AP14: No | AR14: 109681734 | AS14: No | AW14: No | AX14: No
A15: 218541885042464 | C15: 2025-10-04 15:34:45 | D15: delivered | E15: regular | I15: 390 | J15: 15 | K15: 0 | L15: 0 | M15: 0 | N15: 405 | O15: 20.26 | P15: 425.26 | Q15: 425.24 | R15: 22.0% | S15: 93.55 | T15: 0 | U15: 0 | V15: 0 | W15: 0 | X15: 8.5 | Y15: 0 | Z15: 0 | AA15: 0 | AB15: 0 | AC15: 18.36 | AD15: 120.41 | AE15: 0 | AF15: 0 | AG15: 0 | AH15: 20.25 | AI15: 0 | AJ15: 0.41 | AK15: 20.66 | AL15: 284.17 | AM15: No | AN15: 1.85 | AO15: No | AP15: No | AS15: No | AW15: No | AX15: No
A16: 218544791458575 | C16: 2025-10-04 16:23:11 | D16: delivered | E16: regular | H16: TRYNEW | I16: 390 | J16: 15 | K16: 50 | L16: 0 | M16: 50 | N16: 355 | O16: 17.76 | P16: 372.76 | Q16: 372.76 | R16: 22.0% | S16: 82.01 | T16: 0 | U16: 0 | V16: 0 | W16: 3 | X16: 7.46 | Y16: 0 | Z16: 0 | AA16: 0 | AB16: 0 | AC16: 16.64 | AD16: 109.11 | AE16: 0 | AF16: 0 | AG16: 0 | AH16: 17.75 | AI16: 0 | AJ16: 0.35 | AK16: 18.1 | AL16: 245.53 | AM16: No | AN16: 4.695 | AO16: No | AP16: No | AR16: 206500dc-ba9e-4a58-be62-bb3f830ec1f3,206500dc-ba9e-4a58-be62-bb3f830ec1f3 | AS16: No | AW16: Yes | AX16: No
A17: 218553368485905 | C17: 2025-10-04 18:46:08 | D17: delivered | E17: regular | H17: SWIGGYIT | I17: 405 | J17: 15 | K17: 50 | L17: 0 | M17: 50 | N17: 370 | O17: 18.5 | P17: 388.5 | Q17: 388.5 | R17: 22.0% | S17: 85.47 | T17: 0 | U17: 0 | V17: 0 | W17: 3 | X17: 7.77 | Y17: 0 | Z17: 0 | AA17: 0 | AB17: 0 | AC17: 17.32 | AD17: 113.56 | AE17: 0 | AF17: 0 | AG17: 0 | AH17: 18.5 | AI17: 0 | AJ17: 0.37 | AK17: 18.87 | AL17: 256.07 | AM17: No | AN17: 2.907 | AO17: No | AP17: No | AR17: 206500dc-ba9e-4a58-be62-bb3f830ec1f3,0cb1c2c3-eeb3-4e1c-a83e-4606e0952f8f,206500dc-ba9e-4a58-be62-bb3f830ec1f3,0cb1c2c3-eeb3-4e1c-a83e-4606e0952f8f | AS17: No | AW17: Yes | AX17: No
A18: 218557125828287 | C18: 2025-10-04 19:48:45 | D18: delivered | E18: regular | I18: 280 | J18: 10 | K18: 0 | L18: 0 | M18: 0 | N18: 290 | O18: 14.5 | P18: 304.5 | Q18: 304.5 | R18: 22.0% | S18: 66.99 | T18: 0 | U18: 0 | V18: 0 | W18: 0 | X18: 6.09 | Y18: 0 | Z18: 0 | AA18: 0 | AB18: 0 | AC18: 13.16 | AD18: 86.24 | AE18: 0 | AF18: 0 | AG18: 0 | AH18: 14.5 | AI18: 0 | AJ18: 0.29 | AK18: 14.79 | AL18: 203.49 | AM18: No | AN18: 1.386 | AO18: No | AP18: No | AS18: No | AW18: No | AX18: No
A19: 218562566743822 | C19: 2025-10-04 21:19:26 | D19: delivered | E19: regular | H19: SWIGGYIT | I19: 375 | J19: 15 | K19: 50 | L19: 0 | M19: 50 | N19: 340 | O19: 17 | P19: 357 | Q19: 357 | R19: 22.0% | S19: 78.54 | T19: 0 | U19: 0 | V19: 0 | W19: 0 | X19: 7.14 | Y19: 0 | Z19: 0 | AA19: 0 | AB19: 0 | AC19: 15.42 | AD19: 101.1 | AE19: 0 | AF19: 0 | AG19: 0 | AH19: 17 | AI19: 0 | AJ19: 0.34 | AK19: 17.34 | AL19: 238.56 | AM19: No | AN19: 5.593 | AO19: No | AP19: No | AR19: 109681730 | AS19: No | AW19: No | AX19: No
A20: 218570104049086 | C20: 2025-10-04 23:25:04 | D20: cancelled | E20: regular | F20: prepaid | G20: SWIGGY | H20: MISSEDYOU | I20: 290 | J20: 10 | K20: 50 | L20: 0 | M20: 50 | N20: 250 | O20: 12.5 | P20: 262.5 | Q20: 262.5 | R20: 22.0% | S20: 57.75 | T20: 0 | U20: 0 | V20: 0 | W20: 0 | X20: 5.25 | Y20: 0 | Z20: 0 | AA20: 0 | AB20: 0 | AC20: 11.34 | AD20: 74.34 | AE20: 0 | AF20: 0 | AG20: 0 | AH20: 12.5 | AI20: 0 | AJ20: 0.25 | AK20: 12.75 | AL20: 175.41 | AM20: No | AN20: 5.499 | AO20: No | AP20: Yes | AR20: 206500dc-ba9e-4a58-be62-bb3f830ec1f3,206500dc-ba9e-4a58-be62-bb3f830ec1f3 | AS20: No | AU20: 34.366667 | AV20: picked up | AW20: Yes | AX20: No

Sheet D2W1
A1: Adjustments this week
A2: Adjustment Type | B2: Total Amount | C2: Settled Amount | D2: Outstanding Amount | E2: Period From | F2: Period To | G2: Invoice Number | H2: Remarks
A4: Adjustments from previous week
A5: Adjusment Type | B5: Total Amount | C5: Settled Amount | D5: Outstanding Amount | E5: Period From | F5: Period To | G5: Invoice Number | H5: Remarks
A7: Total Adjustments | B7: ₹0.0 | C7: ₹0.0 | D7: ₹0.0

Sheet D1W2
I1: 0 | J1: 0 | K1: 0 | L1: 0 | M1: 0 | N1: 0 | O1: 0 | P1: 0 | Q1: 0 | R1: 0 | S1: 0 | T1: 0 | U1: 0 | V1: 0 | W1: 0 | X1: 0 | Y1: 0 | Z1: 0 | AA1: 0 | AB1: 0 | AC1: 0 | AD1: 0 | AE1: 0 | AF1: 0 | AG1: 0 | AH1: 0 | AI1: 0 | AJ1: 0 | AK1: 0 | AL1: 0 | AM1: 0 | AN1: 0 | AO1: 0 | AP1: 0 | AQ1: 0 | AR1: 0 | AS1: 0 | AT1: 0 | AU1: 0 | AV1: 0 | AW1: 0 | AX1: 0 | AY1: 0 | AZ1: 0 | BA1: 0 | BB1: 0 | BC1: 0 | BD1: 0 | BE1: 0 | BF1: 0 | BG1: 0 | BH1: 0 | BI1: 0 | BJ1: 0 | BK1: 0 | BL1: 0 | BM1: 0 | BN1: 0 | BO1: 0 | BP1: 0 | BQ1: 0 | BR1: 0 | BS1: 0 | BT1: 0 | BU1: 0 | BV1: 0 | BW1: 0 | BX1: 0 | BY1: 0 | BZ1: 0 | CA1: 0 | CB1: 0 | CC1: 0
I2: 18020 | J2: 770 | K2: 1473.87 | L2: 0 | M2: 1473.87 | N2: 17316.13 | O2: 865.84 | P2: 18181.97 | Q2: 18181.95 | R2: 0 | S2: 4000 | T2: 0 | U2: 0 | V2: 0 | W2: 103.88 | X2: 363.64 | Y2: 0 | Z2: 30 | AA2: 0 | AB2: 0 | AC2: 809.6 | AD2: 5307.12 | AE2: 0 | AF2: 46 | AG2: 46 | AH2: 865.8 | AI2: 0 | AJ2: 17.31 | AK2: 883.11 | AL2: 11945.52 | AM2: 0 | AN2: 188.261 | AO2: 0 | AP2: 0 | AQ2: 0 | AR2: 0 | AS2: 0 | AT2: 0 | AU2: 0 | AV2: 0 | AW2: 0 | AX2: 0 | AY2: 0 | AZ2: 0 | BA2: 0 | BB2: 0 | BC2: 0 | BD2: 0 | BE2: 0 | BF2: 0 | BG2: 0 | BH2: 0 | BI2: 0 | BJ2: 0 | BK2: 0 | BL2: 0 | BM2: 0 | BN2: 0 | BO2: 0 | BP2: 0 | BQ2: 0 | BR2: 0 | BS2: 0 | BT2: 0 | BU2: 0 | BV2: 0 | BW2: 0 | BX2: 0 | BY2: 0 | BZ2: 0 | CA2: 0 | CB2: 0 | CC2: 0
I3: 21263.6 | J3: 908.6 | K3: 1739.1666 | L3: 0 | M3: 1739.1666 | N3: 20433.033 | O3: 1021.6912 | P3: 21454.725 | Q3: 21454.701 | R3: 0 | S3: 4720 | T3: 0 | U3: 0 | V3: 0 | W3: 122.5784 | X3: 429.0952 | Y3: 0 | Z3: 35.4 | AA3: 0 | AB3: 0 | AC3: 955.328 | AD3: 6262.4016 | AE3: 0 | AF3: 54.28 | AG3: 54.28 | AH3: 1021.644 | AI3: 0 | AJ3: 20.4258 | AK3: 1042.0698 | AL3: 14095.714 | AM3: 0 | AN3: 222.14798 | AO3: 0 | AP3: 0 | AQ3: 0 | AR3: 0 | AS3: 0 | AT3: 0 | AU3: 0 | AV3: 0 | AW3: 0 | AX3: 0 | AY3: 0 | AZ3: 0 | BA3: 0 | BB3: 0 | BC3: 0 | BD3: 0 | BE3: 0 | BF3: 0 | BG3: 0 | BH3: 0 | BI3: 0 | BJ3: 0 | BK3: 0 | BL3: 0 | BM3: 0 | BN3: 0 | BO3: 0 | BP3: 0 | BQ3: 0 | BR3: 0 | BS3: 0 | BT3: 0 | BU3: 0 | BV3: 0 | BW3: 0 | BX3: 0 | BY3: 0 | BZ3: 0 | CA3: 0 | CB3: 0 | CC3: 0
I4: 18020 | J4: 770 | K4: 1473.87 | L4: 0 | M4: 1473.87 | N4: 17316.13 | O4: 865.84 | P4: 18181.97 | Q4: 18181.95 | R4: 0 | S4: 4000 | T4: 0 | U4: 0 | V4: 0 | W4: 103.88 | X4: 363.64 | Y4: 0 | Z4: 30 | AA4: 0 | AB4: 0 | AC4: 809.6 | AD4: 5307.12 | AE4: 0 | AF4: 46 | AG4: 46 | AH4: 865.8 | AI4: 0 | AJ4: 17.31 | AK4: 883.11 | AL4: 11945.52 | AM4: 0 | AN4: 188.261 | AO4: 0 | AP4: 0 | AQ4: 0 | AR4: 0 | AS4: 0 | AT4: 0 | AU4: 0 | AV4: 0 | AW4: 0 | AX4: 0 | AY4: 0 | AZ4: 0 | BA4: 0 | BB4: 0 | BC4: 0 | BD4: 0 | BE4: 0 | BF4: 0 | BG4: 0 | BH4: 0 | BI4: 0 | BJ4: 0 | BK4: 0 | BL4: 0 | BM4: 0 | BN4: 0 | BO4: 0 | BP4: 0 | BQ4: 0 | BR4: 0 | BS4: 0 | BT4: 0 | BU4: 0 | BV4: 0 | BW4: 0 | BX4: 0 | BY4: 0 | BZ4: 0 | CA4: 0 | CB4: 0 | CC4: 0
A5: Order ID | B5: Parent Order ID | C5: Order Date | D5: Order Status | E5: Order Category | F5: Order Payment Type | G5: Cancelled By? | H5: Coupon type applied by customer | I5: Item Total | J5: Packaging Charges | K5: Restaurant Discounts (Promo, Freebies, Flat Off, etc.) | L5: Swiggy One Exclusive Offer Discount | M5: Restaurant Discount Share [3a+3b] | N5: Net Bill Value (before taxes) [1+2-3] | O5: GST Collected | P5: Total Customer Paid [4+5] | Q5: Commission charged on | R5: Service Fees % | S5: Commission | T5: Long Distance Charges | U5: Discount on Long Distance Fee | V5: Pocket Hero Fees | W5: Swiggy One Fees | X5: Payment Collection Charges | Y5: Restaurant Cancellation Charges | Z5: Call Center Charges | AA5: Delivery Fee sponsored by Restaurant (w/o tax) | AB5: Bolt Fees | AC5: GST on Service Fee @18% | AD5: Total Swiggy Fees [6+7+8-9+10+11+12+13+14+15+16] | AE5: Customer Cancellations | AF5: Customer Complaints | AG5: Complaint & Cancellation Charges [17+18] | AH5: GST Deduction | AI5: TCS | AJ5: TDS | AK5: Total Taxes [19+20+21] | AL5: Net Payout for Order (after taxes) [A-B-C-D] | AM5: Long Distance Order | AN5: Last Mile (in km) | AO5: MFR Accurate? | AP5: MFR Pressed? | AQ5: Coupon Code Sourced | AR5: Discount Campaign ID | AS5: Replicated Order | AT5: Base order ID | AU5: Cancellation time | AV5: Pick Up Status | AW5: Swiggy One Customer? | AX5: Pocket Hero Order?
A6: 218572200016275 | C6: 2025-10-05 00:00:00 | D6: delivered | E6: regular | I6: 290 | J6: 10 | K6: 0 | L6: 0 | M6: 0 | N6: 300 | O6: 15 | P6: 315 | Q6: 315 | R6: 22.0% | S6: 69.3 | T6: 0 | U6: 0 | V6: 0 | W6: 3.71 | X6: 6.3 | Y6: 0 | Z6: 0 | AA6: 0 | AB6: 0 | AC6: 14.28 | AD6: 93.59 | AE6: 0 | AF6: 0 | AG6: 0 | AH6: 15 | AI6: 0 | AJ6: 0.3 | AK6: 15.3 | AL6: 206.1 | AM6: No | AN6: 5.499 | AO6: No | AP6: No | AR6: 206500dc-ba9e-4a58-be62-bb3f830ec1f3 | AS6: Yes | AT6: 218570104049086 | AW6: Yes | AX6: No
A7: 218635323782297 | C7: 2025-10-05 17:32:03 | D7: delivered | E7: regular | H7: FLAT100 | I7: 1240 | J7: 50 | K7: 99.98 | L7: 0 | M7: 99.98 | N7: 1190.02 | O7: 59.5 | P7: 1249.52 | Q7: 1249.52 | R7: 22.0% | S7: 274.89 | T7: 0 | U7: 0 | V7: 0 | W7: 3.71 | X7: 24.99 | Y7: 0 | Z7: 0 | AA7: 0 | AB7: 0 | AC7: 54.64 | AD7: 358.23 | AE7: 0 | AF7: 0 | AG7: 0 | AH7: 59.5 | AI7: 0 | AJ7: 1.19 | AK7: 60.69 | AL7: 830.59 | AM7: No | AN7: 10.823 | AO7: No | AP7: No | AR7: 104304725 | AS7: No | AW7: Yes | AX7: No
A8: 218635352921799 | C8: 2025-10-05 17:32:32 | D8: delivered | E8: regular | H8: SWIGGYIT | I8: 230 | J8: 10 | K8: 46 | L8: 0 | M8: 46 | N8: 194 | O8: 9.7 | P8: 203.7 | Q8: 203.7 | R8: 22.0% | S8: 44.81 | T8: 0 | U8: 0 | V8: 0 | W8: 3.71 | X8: 4.07 | Y8: 0 | Z8: 0 | AA8: 0 | AB8: 0 | AC8: 9.46 | AD8: 62.05 | AE8: 0 | AF8: 46 | AG8: 46 | AH8: 9.7 | AI8: 0 | AJ8: 0.19 | AK8: 9.89 | AL8: 85.74 | AM8: No | AN8: 7.864 | AO8: No | AP8: No | AR8: 109681730 | AS8: No | AW8: Yes | AX8: No
A9: 218637868248054 | C9: 2025-10-05 18:14:28 | D9: delivered | E9: regular | H9: SWIGGYIT | I9: 375 | J9: 15 | K9: 50 | L9: 0 | M9: 50 | N9: 340 | O9: 17 | P9: 357 | Q9: 357 | R9: 22.0% | S9: 78.54 | T9: 0 | U9: 0 | V9: 0 | W9: 3.71 | X9: 7.14 | Y9: 0 | Z9: 0 | AA9: 0 | AB9: 0 | AC9: 16.1 | AD9: 105.49 | AE9: 0 | AF9: 0 | AG9: 0 | AH9: 17 | AI9: 0 | AJ9: 0.34 | AK9: 17.34 | AL9: 234.17 | AM9: No | AN9: 2.912 | AO9: No | AP9: No | AR9: 39d32da7-47a1-4788-bf6b-1e869bb94cbb,206500dc-ba9e-4a58-be62-bb3f830ec1f3,39d32da7-47a1-4788-bf6b-1e869bb94cbb,206500dc-ba9e-4a58-be62-bb3f830ec1f3 | AS9: No | AW9: Yes | AX9: No
A10: 218645376352712 | C10: 2025-10-05 20:19:36 | D10: delivered | E10: regular | H10: TRYNEW | I10: 460 | J10: 20 | K10: 50 | L10: 0 | M10: 50 | N10: 430 | O10: 21.5 | P10: 451.5 | Q10: 451.5 | R10: 22.0% | S10: 99.33 | T10: 0 | U10: 0 | V10: 0 | W10: 3.71 | X10: 9.03 | Y10: 0 | Z10: 10 | AA10: 0 | AB10: 0 | AC10: 21.98 | AD10: 144.05 | AE10: 0 | AF10: 0 | AG10: 0 | AH10: 21.5 | AI10: 0 | AJ10: 0.43 | AK10: 21.93 | AL10: 285.52 | AM10: No | AN10: 9.347 | AO10: No | AP10: No | AR10: 109681737 | AS10: No | AW10: Yes | AX10: No
A11: 218651169644535 | C11: 2025-10-05 21:56:09 | D11: delivered | E11: regular | H11: TRYNEW | I11: 230 | J11: 10 | K11: 46 | L11: 0 | M11: 46 | N11: 194 | O11: 9.7 | P11: 203.7 | Q11: 203.7 | R11: 22.0% | S11: 44.81 | T11: 0 | U11: 0 | V11: 0 | W11: 3.71 | X11: 4.07 | Y11: 0 | Z11: 0 | AA11: 0 | AB11: 0 | AC11: 9.46 | AD11: 62.05 | AE11: 0 | AF11: 0 | AG11: 0 | AH11: 9.7 | AI11: 0 | AJ11: 0.19 | AK11: 9.89 | AL11: 131.74 | AM11: No | AN11: 1.959 | AO11: No | AP11: No | AR11: b6af2f0d-471c-4ad4-bb94-cf8a7dd3fac9,206500dc-ba9e-4a58-be62-bb3f830ec1f3,b6af2f0d-471c-4ad4-bb94-cf8a7dd3fac9,206500dc-ba9e-4a58-be62-bb3f830ec1f3 | AS11: No | AW11: Yes | AX11: No
A12: 218651249285329 | C12: 2025-10-05 21:57:29 | D12: delivered | E12: regular | I12: 1100 | J12: 50 | K12: 0 | L12: 0 | M12: 0 | N12: 1150 | O12: 57.5 | P12: 1207.5 | Q12: 1207.5 | R12: 22.0% | S12: 265.65 | T12: 0 | U12: 0 | V12: 0 | W12: 0 | X12: 24.15 | Y12: 0 | Z12: 0 | AA12: 0 | AB12: 0 | AC12: 52.16 | AD12: 341.96 | AE12: 0 | AF12: 0 | AG12: 0 | AH12: 57.5 | AI12: 0 | AJ12: 1.15 | AK12: 58.65 | AL12: 806.89 | AM12: No | AN12: 5.008 | AO12: No | AP12: No | AS12: No | AW12: No | AX12: No
A13: 218655612300199 | C13: 2025-10-05 23:10:12 | D13: delivered | E13: regular | H13: SWIGGYIT | I13: 460 | J13: 20 | K13: 50 | L13: 0 | M13: 50 | N13: 430 | O13: 21.5 | P13: 451.5 | Q13: 451.5 | R13: 22.0% | S13: 99.33 | T13: 0 | U13: 0 | V13: 0 | W13: 3.71 | X13: 9.03 | Y13: 0 | Z13: 0 | AA13: 0 | AB13: 0 | AC13: 20.18 | AD13: 132.25 | AE13: 0 | AF13: 0 | AG13: 0 | AH13: 21.5 | AI13: 0 | AJ13: 0.43 | AK13: 21.93 | AL13: 297.32 | AM13: No | AN13: 2.392 | AO13: No | AP13: No | AR13: 98a29174-a6e3-4af4-b247-824cb31c90a5,206500dc-ba9e-4a58-be62-bb3f830ec1f3,98a29174-a6e3-4af4-b247-824cb31c90a5,206500dc-ba9e-4a58-be62-bb3f830ec1f3 | AS13: No | AW13: Yes | AX13: No
A14: 218714820453375 | C14: 2025-10-06 15:37:00 | D14: delivered | E14: regular | H14: TRYNEW | I14: 390 | J14: 20 | K14: 49.99 | L14: 0 | M14: 49.99 | N14: 360.01 | O14: 18 | P14: 378.01 | Q14: 378.01 | R14: 22.0% | S14: 83.16 | T14: 0 | U14: 0 | V14: 0 | W14: 3.71 | X14: 7.56 | Y14: 0 | Z14: 0 | AA14: 0 | AB14: 0 | AC14: 17 | AD14: 111.43 | AE14: 0 | AF14: 0 | AG14: 0 | AH14: 18 | AI14: 0 | AJ14: 0.36 | AK14: 18.36 | AL14: 248.21 | AM14: No | AN14: 7.577 | AO14: No | AP14: No | AR14: 0023092f-8696-4e03-a7fc-2e6bb98421e7,0023092f-8696-4e03-a7fc-2e6bb98421e7 | AS14: No | AW14: Yes | AX14: No
A15: 218715903715435 | C15: 2025-10-06 15:55:03 | D15: delivered | E15: regular | I15: 520 | J15: 20 | K15: 0 | L15: 0 | M15: 0 | N15: 540 | O15: 27 | P15: 567 | Q15: 567 | R15: 22.0% | S15: 124.74 | T15: 0 | U15: 0 | V15: 0 | W15: 3.71 | X15: 11.34 | Y15: 0 | Z15: 0 | AA15: 0 | AB15: 0 | AC15: 25.16 | AD15: 164.95 | AE15: 0 | AF15: 0 | AG15: 0 | AH15: 27 | AI15: 0 | AJ15: 0.54 | AK15: 27.54 | AL15: 374.51 | AM15: No | AN15: 4.785 | AO15: No | AP15: No | AR15: 206500dc-ba9e-4a58-be62-bb3f830ec1f3 | AS15: No | AW15: Yes | AX15: No
A16: 218720190813592 | C16: 2025-10-06 17:06:30 | D16: delivered | E16: regular | H16: FLAT100 | I16: 835 | J16: 35 | K16: 99.99 | L16: 0 | M16: 99.99 | N16: 770.01 | O16: 38.5 | P16: 808.51 | Q16: 808.51 | R16: 22.0% | S16: 177.87 | T16: 0 | U16: 0 | V16: 0 | W16: 3.71 | X16: 16.17 | Y16: 0 | Z16: 0 | AA16: 0 | AB16: 0 | AC16: 35.6 | AD16: 233.35 | AE16: 0 | AF16: 0 | AG16: 0 | AH16: 38.5 | AI16: 0 | AJ16: 0.77 | AK16: 39.27 | AL16: 535.88 | AM16: No | AN16: 5.475 | AO16: No | AP16: No | AR16: 206500dc-ba9e-4a58-be62-bb3f830ec1f3,206500dc-ba9e-4a58-be62-bb3f830ec1f3 | AS16: No | AW16: Yes | AX16: No
A17: 218733697347141 | C17: 2025-10-06 20:51:37 | D17: delivered | E17: regular | H17: SWIGGYIT | I17: 510 | J17: 20 | K17: 49.99 | L17: 0 | M17: 49.99 | N17: 480.01 | O17: 24 | P17: 504.01 | Q17: 504.01 | R17: 22.0% | S17: 110.88 | T17: 0 | U17: 0 | V17: 0 | W17: 3.71 | X17: 10.08 | Y17: 0 | Z17: 0 | AA17: 0 | AB17: 0 | AC17: 22.44 | AD17: 147.11 | AE17: 0 | AF17: 0 | AG17: 0 | AH17: 24 | AI17: 0 | AJ17: 0.48 | AK17: 24.48 | AL17: 332.42 | AM17: No | AN17: 2.053 | AO17: No | AP17: No | AR17: 2f413918-5a08-4ae4-8ca8-2aeafa0e9c12,206500dc-ba9e-4a58-be62-bb3f830ec1f3,2f413918-5a08-4ae4-8ca8-2aeafa0e9c12,206500dc-ba9e-4a58-be62-bb3f830ec1f3 | AS17: No | AW17: Yes | AX17: No
A18: 218733699392911 | C18: 2025-10-06 20:51:39 | D18: delivered | E18: regular | H18: SWIGGYIT | I18: 280 | J18: 10 | K18: 50 | L18: 0 | M18: 50 | N18: 240 | O18: 12 | P18: 252 | Q18: 252 | R18: 22.0% | S18: 55.44 | T18: 0 | U18: 0 | V18: 0 | W18: 3.71 | X18: 5.04 | Y18: 0 | Z18: 0 | AA18: 0 | AB18: 0 | AC18: 11.56 | AD18: 75.75 | AE18: 0 | AF18: 0 | AG18: 0 | AH18: 12 | AI18: 0 | AJ18: 0.24 | AK18: 12.24 | AL18: 164 | AM18: No | AN18: 0.104 | AO18: No | AP18: No | AR18: 206500dc-ba9e-4a58-be62-bb3f830ec1f3,206500dc-ba9e-4a58-be62-bb3f830ec1f3 | AS18: No | AW18: Yes | AX18: No
A19: 218735334448293 | C19: 2025-10-06 21:18:54 | D19: delivered | E19: regular | H19: TRYNEW | I19: 695 | J19: 35 | K19: 49.99 | L19: 0 | M19: 49.99 | N19: 680.01 | O19: 34 | P19: 714.01 | Q19: 714.01 | R19: 22.0% | S19: 157.08 | T19: 0 | U19: 0 | V19: 0 | W19: 0 | X19: 14.28 | Y19: 0 | Z19: 0 | AA19: 0 | AB19: 0 | AC19: 30.84 | AD19: 202.2 | AE19: 0 | AF19: 0 | AG19: 0 | AH19: 34 | AI19: 0 | AJ19: 0.68 | AK19: 34.68 | AL19: 477.12 | AM19: No | AN19: 9.253 | AO19: No | AP19: No | AR19: e54cb258-176a-4272-b740-73674c1abce4,e54cb258-176a-4272-b740-73674c1abce4 | AS19: No | AW19: No | AX19: No
A20: 218739527721689 | C20: 2025-10-06 22:28:47 | D20: delivered | E20: regular | H20: MISSEDYOU | I20: 605 | J20: 25 | K20: 49.99 | L20: 0 | M20: 49.99 | N20: 580.01 | O20: 29 | P20: 609.01 | Q20: 609.01 | R20: 22.0% | S20: 133.98 | T20: 0 | U20: 0 | V20: 0 | W20: 3.71 | X20: 12.18 | Y20: 0 | Z20: 0 | AA20: 0 | AB20: 0 | AC20: 26.98 | AD20: 176.85 | AE20: 0 | AF20: 0 | AG20: 0 | AH20: 29 | AI20: 0 | AJ20: 0.58 | AK20: 29.58 | AL20: 402.57 | AM20: No | AN20: 5.513 | AO20: No | AP20: No | AR20: 206500dc-ba9e-4a58-be62-bb3f830ec1f3,206500dc-ba9e-4a58-be62-bb3f830ec1f3 | AS20: No | AW20: Yes | AX20: No
A21: 218795997557221 | C21: 2025-10-07 14:09:57 | D21: delivered | E21: regular | I21: 270 | J21: 10 | K21: 0 | L21: 0 | M21: 0 | N21: 280 | O21: 14 | P21: 294 | Q21: 294 | R21: 22.0% | S21: 64.68 | T21: 0 | U21: 0 | V21: 0 | W21: 3.71 | X21: 5.88 | Y21: 0 | Z21: 0 | AA21: 0 | AB21: 0 | AC21: 13.36 | AD21: 87.63 | AE21: 0 | AF21: 0 | AG21: 0 | AH21: 14 | AI21: 0 | AJ21: 0.28 | AK21: 14.28 | AL21: 192.08 | AM21: No | AN21: 1.334 | AO21: No | AP21: No | AR21: 206500dc-ba9e-4a58-be62-bb3f830ec1f3,b186a181-c6da-41d8-8b06-ccf5d4bc72cf | AS21: No | AW21: Yes | AX21: No
A22: 218822250729837 | C22: 2025-10-07 21:27:30 | D22: delivered | E22: regular | H22: SWIGGYIT | I22: 605 | J22: 25 | K22: 49.99 | L22: 0 | M22: 49.99 | N22: 580.01 | O22: 29 | P22: 609.01 | Q22: 609.01 | R22: 22.0% | S22: 133.98 | T22: 0 | U22: 0 | V22: 0 | W22: 0 | X22: 12.18 | Y22: 0 | Z22: 0 | AA22: 0 | AB22: 0 | AC22: 26.3 | AD22: 172.46 | AE22: 0 | AF22: 0 | AG22: 0 | AH22: 29 | AI22: 0 | AJ22: 0.58 | AK22: 29.58 | AL22: 406.95 | AM22: No | AN22: 4.519 | AO22: No | AP22: No | AR22: 109681730 | AS22: No | AW22: No | AX22: No
A23: 218824499920250 | C23: 2025-10-07 22:04:59 | D23: delivered | E23: regular | H23: MISSEDYOU | I23: 160 | J23: 10 | K23: 32 | L23: 0 | M23: 32 | N23: 138 | O23: 6.9 | P23: 144.9 | Q23: 144.9 | R23: 22.0% | S23: 31.88 | T23: 0 | U23: 0 | V23: 0 | W23: 3.71 | X23: 2.9 | Y23: 0 | Z23: 0 | AA23: 0 | AB23: 0 | AC23: 6.92 | AD23: 45.41 | AE23: 0 | AF23: 0 | AG23: 0 | AH23: 6.9 | AI23: 0 | AJ23: 0.14 | AK23: 7.04 | AL23: 92.44 | AM23: No | AN23: 4.588 | AO23: No | AP23: No | AR23: 206500dc-ba9e-4a58-be62-bb3f830ec1f3,d3df4fe6-6adc-42d7-9751-8481f0ebc05c,206500dc-ba9e-4a58-be62-bb3f830ec1f3,d3df4fe6-6adc-42d7-9751-8481f0ebc05c | AS23: No | AW23: Yes | AX23: No
A24: 218827004245379 | C24: 2025-10-07 22:46:44 | D24: delivered | E24: regular | I24: 230 | J24: 10 | K24: 0 | L24: 0 | M24: 0 | N24: 240 | O24: 12 | P24: 252 | Q24: 252 | R24: 22.0% | S24: 55.44 | T24: 0 | U24: 0 | V24: 0 | W24: 3.71 | X24: 5.04 | Y24: 0 | Z24: 0 | AA24: 0 | AB24: 0 | AC24: 11.56 | AD24: 75.75 | AE24: 0 | AF24: 0 | AG24: 0 | AH24: 12 | AI24: 0 | AJ24: 0.24 | AK24: 12.24 | AL24: 164 | AM24: No | AN24: 5.202 | AO24: No | AP24: No | AR24: c27ba60a-db89-4a3c-92e0-c7c699a2c289,206500dc-ba9e-4a58-be62-bb3f830ec1f3 | AS24: No | AW24: Yes | AX24: No
A25: 218885659640951 | C25: 2025-10-08 15:04:19 | D25: delivered | E25: regular | H25: SWIGGYIT | I25: 460 | J25: 20 | K25: 50 | L25: 0 | M25: 50 | N25: 430 | O25: 21.5 | P25: 451.5 | Q25: 451.5 | R25: 22.0% | S25: 99.33 | T25: 0 | U25: 0 | V25: 0 | W25: 3.71 | X25: 9.03 | Y25: 0 | Z25: 0 | AA25: 0 | AB25: 0 | AC25: 20.18 | AD25: 132.25 | AE25: 0 | AF25: 0 | AG25: 0 | AH25: 21.5 | AI25: 0 | AJ25: 0.43 | AK25: 21.93 | AL25: 297.32 | AM25: No | AN25: 10.231 | AO25: No | AP25: No | AR25: 109681730 | AS25: No | AW25: Yes | AX25: No
A26: 218889073179670 | C26: 2025-10-08 16:01:13 | D26: delivered | E26: regular | H26: ONEBLCK75 | I26: 460 | J26: 20 | K26: 50 | L26: 0 | M26: 50 | N26: 430 | O26: 21.5 | P26: 451.5 | Q26: 451.5 | R26: 22.0% | S26: 99.33 | T26: 0 | U26: 0 | V26: 0 | W26: 3.71 | X26: 9.03 | Y26: 0 | Z26: 0 | AA26: 0 | AB26: 0 | AC26: 20.18 | AD26: 132.25 | AE26: 0 | AF26: 0 | AG26: 0 | AH26: 21.5 | AI26: 0 | AJ26: 0.43 | AK26: 21.93 | AL26: 297.32 | AM26: No | AN26: 5.532 | AO26: No | AP26: No | AQ26: SWIGGYIT | AR26: d64389e9-2d76-460c-9ec8-2a38ff64f2b3,206500dc-ba9e-4a58-be62-bb3f830ec1f3,d64389e9-2d76-460c-9ec8-2a38ff64f2b3,206500dc-ba9e-4a58-be62-bb3f830ec1f3 | AS26: No | AW26: Yes | AX26: No
A27: 218900034280050 | C27: 2025-10-08 19:03:54 | D27: delivered | E27: regular | I27: 390 | J27: 15 | K27: 0 | L27: 0 | M27: 0 | N27: 405 | O27: 20.26 | P27: 425.26 | Q27: 425.24 | R27: 22.0% | S27: 93.55 | T27: 0 | U27: 0 | V27: 0 | W27: 3.71 | X27: 8.5 | Y27: 0 | Z27: 0 | AA27: 0 | AB27: 0 | AC27: 19.04 | AD27: 124.8 | AE27: 0 | AF27: 0 | AG27: 0 | AH27: 20.25 | AI27: 0 | AJ27: 0.41 | AK27: 20.66 | AL27: 279.78 | AM27: No | AN27: 8.542 | AO27: No | AP27: No | AS27: No | AW27: Yes | AX27: No
A28: 218963495395510 | C28: 2025-10-09 12:41:35 | D28: delivered | E28: regular | H28: TRYNEW | I28: 390 | J28: 15 | K28: 50 | L28: 0 | M28: 50 | N28: 355 | O28: 17.76 | P28: 372.76 | Q28: 372.76 | R28: 22.0% | S28: 82.01 | T28: 0 | U28: 0 | V28: 0 | W28: 3.71 | X28: 7.46 | Y28: 0 | Z28: 0 | AA28: 0 | AB28: 0 | AC28: 16.78 | AD28: 109.96 | AE28: 0 | AF28: 0 | AG28: 0 | AH28: 17.75 | AI28: 0 | AJ28: 0.35 | AK28: 18.1 | AL28: 244.69 | AM28: No | AN28: 9.074 | AO28: No | AP28: No | AR28: 109681737 | AS28: No | AW28: Yes | AX28: No
A29: 218978970723060 | C29: 2025-10-09 16:59:30 | D29: delivered | E29: regular | I29: 230 | J29: 10 | K29: 0 | L29: 0 | M29: 0 | N29: 240 | O29: 12 | P29: 252 | Q29: 252 | R29: 22.0% | S29: 55.44 | T29: 0 | U29: 0 | V29: 0 | W29: 3.71 | X29: 5.04 | Y29: 0 | Z29: 0 | AA29: 0 | AB29: 0 | AC29: 11.56 | AD29: 75.75 | AE29: 0 | AF29: 0 | AG29: 0 | AH29: 12 | AI29: 0 | AJ29: 0.24 | AK29: 12.24 | AL29: 164 | AM29: No | AN29: 1.972 | AO29: No | AP29: No | AR29: 206500dc-ba9e-4a58-be62-bb3f830ec1f3 | AS29: No | AW29: Yes | AX29: No
A30: 218987566857939 | C30: 2025-10-09 19:22:46 | D30: delivered | E30: regular | I30: 500 | J30: 20 | K30: 0 | L30: 0 | M30: 0 | N30: 520 | O30: 26 | P30: 546 | Q30: 546 | R30: 22.0% | S30: 120.12 | T30: 0 | U30: 0 | V30: 0 | W30: 3.71 | X30: 10.92 | Y30: 0 | Z30: 0 | AA30: 0 | AB30: 0 | AC30: 24.26 | AD30: 159.01 | AE30: 0 | AF30: 0 | AG30: 0 | AH30: 26 | AI30: 0 | AJ30: 0.52 | AK30: 26.52 | AL30: 360.46 | AM30: No | AN30: 7.924 | AO30: No | AP30: No | AS30: No | AW30: Yes | AX30: No
A31: 219081832164823 | C31: 2025-10-10 21:33:52 | D31: delivered | E31: regular | H31: FLAT100 | I31: 1560 | J31: 65 | K31: 99.99 | L31: 0 | M31: 99.99 | N31: 1525.01 | O31: 76.26 | P31: 1601.27 | Q31: 1601.27 | R31: 22.0% | S31: 352.28 | T31: 0 | U31: 0 | V31: 0 | W31: 3.71 | X31: 32.03 | Y31: 0 | Z31: 0 | AA31: 0 | AB31: 0 | AC31: 69.84 | AD31: 457.86 | AE31: 0 | AF31: 0 | AG31: 0 | AH31: 76.25 | AI31: 0 | AJ31: 1.53 | AK31: 77.78 | AL31: 1065.62 | AM31: No | AN31: 5.125 | AO31: No | AP31: No | AR31: 206500dc-ba9e-4a58-be62-bb3f830ec1f3,206500dc-ba9e-4a58-be62-bb3f830ec1f3 | AS31: No | AW31: Yes | AX31: No
A32: 219139657996648 | C32: 2025-10-11 13:37:37 | D32: delivered | E32: regular | H32: TRYNEW | I32: 320 | J32: 20 | K32: 50 | L32: 0 | M32: 50 | N32: 290 | O32: 14.5 | P32: 304.5 | Q32: 304.5 | R32: 22.0% | S32: 66.99 | T32: 0 | U32: 0 | V32: 0 | W32: 3.71 | X32: 6.09 | Y32: 0 | Z32: 10 | AA32: 0 | AB32: 0 | AC32: 15.62 | AD32: 102.41 | AE32: 0 | AF32: 0 | AG32: 0 | AH32: 14.5 | AI32: 0 | AJ32: 0.29 | AK32: 14.79 | AL32: 187.3 | AM32: No | AN32: 5.704 | AO32: No | AP32: No | AR32: 206500dc-ba9e-4a58-be62-bb3f830ec1f3,206500dc-ba9e-4a58-be62-bb3f830ec1f3 | AS32: No | AW32: Yes | AX32: No
A33: 219144005420059 | C33: 2025-10-11 14:50:05 | D33: delivered | E33: regular | H33: FLAT100 | I33: 1070 | J33: 40 | K33: 99.98 | L33: 0 | M33: 99.98 | N33: 1010.02 | O33: 50.5 | P33: 1060.52 | Q33: 1060.52 | R33: 22.0% | S33: 233.31 | T33: 0 | U33: 0 | V33: 0 | W33: 0 | X33: 21.21 | Y33: 0 | Z33: 10 | AA33: 0 | AB33: 0 | AC33: 47.62 | AD33: 312.14 | AE33: 0 | AF33: 0 | AG33: 0 | AH33: 50.5 | AI33: 0 | AJ33: 1.01 | AK33: 51.51 | AL33: 696.89 | AM33: No | AN33: 8.542 | AO33: No | AP33: No | AR33: de0f3896-574d-4b13-97af-2256adc5ee67,de0f3896-574d-4b13-97af-2256adc5ee67 | AS33: No | AW33: No | AX33: No
A34: 219152292299235 | C34: 2025-10-11 17:08:12 | D34: delivered | E34: regular | H34: SWIGGYIT | I34: 460 | J34: 20 | K34: 50 | L34: 0 | M34: 50 | N34: 430 | O34: 21.5 | P34: 451.5 | Q34: 451.5 | R34: 22.0% | S34: 99.33 | T34: 0 | U34: 0 | V34: 0 | W34: 3.71 | X34: 9.03 | Y34: 0 | Z34: 0 | AA34: 0 | AB34: 0 | AC34: 20.18 | AD34: 132.25 | AE34: 0 | AF34: 0 | AG34: 0 | AH34: 21.5 | AI34: 0 | AJ34: 0.43 | AK34: 21.93 | AL34: 297.32 | AM34: No | AN34: 10.231 | AO34: No | AP34: No | AR34: 109681730 | AS34: No | AW34: Yes | AX34: No
A35: 219162316266974 | C35: 2025-10-11 19:55:16 | D35: delivered | E35: regular | H35: FLAT100 | I35: 1200 | J35: 50 | K35: 99.99 | L35: 0 | M35: 99.99 | N35: 1150.01 | O35: 57.5 | P35: 1207.51 | Q35: 1207.51 | R35: 22.0% | S35: 265.65 | T35: 0 | U35: 0 | V35: 0 | W35: 0 | X35: 24.15 | Y35: 0 | Z35: 0 | AA35: 0 | AB35: 0 | AC35: 52.16 | AD35: 341.96 | AE35: 0 | AF35: 0 | AG35: 0 | AH35: 57.5 | AI35: 0 | AJ35: 1.15 | AK35: 58.65 | AL35: 806.9 | AM35: No | AN35: 3.324 | AO35: No | AP35: No | AR35: 104304725 | AS35: No | AW35: No | AX35: No
A36: 219164271860516 | C36: 2025-10-11 20:27:51 | D36: delivered | E36: regular | H36: TRYNEW | I36: 605 | J36: 25 | K36: 49.99 | L36: 0 | M36: 49.99 | N36: 580.01 | O36: 29 | P36: 609.01 | Q36: 609.01 | R36: 22.0% | S36: 133.98 | T36: 0 | U36: 0 | V36: 0 | W36: 3.71 | X36: 12.18 | Y36: 0 | Z36: 0 | AA36: 0 | AB36: 0 | AC36: 26.98 | AD36: 176.85 | AE36: 0 | AF36: 0 | AG36: 0 | AH36: 29 | AI36: 0 | AJ36: 0.58 | AK36: 29.58 | AL36: 402.57 | AM36: No | AN36: 4.466 | AO36: No | AP36: No | AR36: 206500dc-ba9e-4a58-be62-bb3f830ec1f3,206500dc-ba9e-4a58-be62-bb3f830ec1f3 | AS36: No | AW36: Yes | AX36: No
A37: 219176478083194 | C37: 2025-10-11 23:51:18 | D37: delivered | E37: regular | H37: TRYNEW | I37: 500 | J37: 30 | K37: 50 | L37: 0 | M37: 50 | N37: 480 | O37: 24 | P37: 504 | Q37: 504 | R37: 22.0% | S37: 110.88 | T37: 0 | U37: 0 | V37: 0 | W37: 3.71 | X37: 10.08 | Y37: 0 | Z37: 0 | AA37: 0 | AB37: 0 | AC37: 22.44 | AD37: 147.11 | AE37: 0 | AF37: 0 | AG37: 0 | AH37: 24 | AI37: 0 | AJ37: 0.48 | AK37: 24.48 | AL37: 332.41 | AM37: No | AN37: 4.029 | AO37: No | AP37: No | AR37: 206500dc-ba9e-4a58-be62-bb3f830ec1f3,206500dc-ba9e-4a58-be62-bb3f830ec1f3 | AS37: No | AW37: Yes | AX37: No
A38: 219176541232685 | C38: 2025-10-11 23:52:21 | D38: delivered | E38: regular | H38: SWIGGYIT | I38: 390 | J38: 15 | K38: 50 | L38: 0 | M38: 50 | N38: 355 | O38: 17.76 | P38: 372.76 | Q38: 372.76 | R38: 22.0% | S38: 82.01 | T38: 0 | U38: 0 | V38: 0 | W38: 3.71 | X38: 7.46 | Y38: 0 | Z38: 0 | AA38: 0 | AB38: 0 | AC38: 16.78 | AD38: 109.96 | AE38: 0 | AF38: 0 | AG38: 0 | AH38: 17.75 | AI38: 0 | AJ38: 0.35 | AK38: 18.1 | AL38: 244.69 | AM38: No | AN38: 7.358 | AO38: No | AP38: No | AR38: 1822c7c8-5532-4e33-8f8f-8e6f264b1ef3,1822c7c8-5532-4e33-8f8f-8e6f264b1ef3 | AS38: No | AW38: Yes | AX38: No

Sheet D2W2
A1: Adjustments this week
A2: Adjustment Type | B2: Total Amount | C2: Settled Amount | D2: Outstanding Amount | E2: Period From | F2: Period To | G2: Invoice Number | H2: Remarks
