Workbook
Name Summary: #REF!

Sheet Summary
B1: Rocktail Hospitality Services (This is it Cafe)
B2: Swiggy Summary - July 2025
B4: Details | C4: 1st to 5th | D4: 6th to 12th | E4: 13th to 19th | F4: 20th to 26th | G4: 27th to 31st | H4: Total
B6: No.of orders | C6: 1209 | D6: 1455 | E6: 1477 | F6: 1242 | G6: 482 | H6: =SUM(C6:G6)
B8: Total Income (Number that you see on Swiggy dashboard) | C8: =Cashflow!C10 | D8: =Cashflow!D10 | E8: =Cashflow!E10 | F8: =Cashflow!F10 | G8: =Cashflow!G10 | H8: =SUM(C8:G8)
B10: Avg. order value | C10: =IFERROR(C8/C60,) | D10: =IFERROR(D8/D6,0) | E10: =IFERROR(E8/E6,0) | F10: =IFERROR(F8/F6,0) | G10: =IFERROR(G8/G6,0) | H10: =IFERROR(H8/H6,0)
B12: No of Disputed Orders | C12: 0 | D12: 0 | E12: 0 | F12: 0 | G12: 0 | H12: =SUM(C12:G12)
B14: Refund amount for disputed orders | C14: =Cashflow!C13 | D14: =Cashflow!D13 | E14: =Cashflow!E13 | F14: =Cashflow!F13 | G14: =Cashflow!G13 | H14: =SUM(C14:G14)
B15: Discounts | C15: =Cashflow!C8 | D15: =Cashflow!D8 | E15: =Cashflow!E8 | F15: =Cashflow!F8 | G15: =Cashflow!G8 | H15: =SUM(C15:G15)
C16: =IFERROR(C15/C8,0) | D16: =IFERROR(D15/D8,0) | E16: =IFERROR(E15/E8,0) | F16: =IFERROR(F15/F8,0) | G16: =IFERROR(G15/G8,0) | H16: =IFERROR(H15/H8,0)
B17: Commission | C17: =Cashflow!C11 | D17: =Cashflow!D11 | E17: =Cashflow!E11 | F17: =Cashflow!F11 | G17: =Cashflow!G11 | H17: =SUM(C17:G17)
B18: (Calculated on Sales + GST) | C18: =IFERROR(C17/C8,0) | D18: =IFERROR(D17/D8,0) | E18: =IFERROR(E17/E8,0) | F18: =IFERROR(F17/F8,0) | G18: =IFERROR(G17/G8,0) | H18: =IFERROR(H17/H8,0)
B19: Marketing & Ads | C19: =Cashflow!C16 | D19: =Cashflow!D16 | E19: =Cashflow!E16 | F19: =Cashflow!F16 | G19: =Cashflow!G16 | H19: =SUM(C19:G19)
C20: =IFERROR(C19/C8,0) | D20: =IFERROR(D19/D8,0) | E20: =IFERROR(E19/E8,0) | F20: =IFERROR(F19/F8,0) | G20: =IFERROR(G19/G8,0) | H20: =IFERROR(H19/H8,0)
B21: Other charges & Tax Adjustments | C21: =Cashflow!C20+Cashflow!C25 | D21: =Cashflow!D20+Cashflow!D25 | E21: =Cashflow!E20+Cashflow!E25 | F21: =Cashflow!F20+Cashflow!F25 | G21: =Cashflow!G20+Cashflow!G25 | H21: =SUM(C21:G21)
C22: =IFERROR(C21/C8,0) | D22: =IFERROR(D21/D8,0) | E22: =IFERROR(E21/E8,0) | F22: =IFERROR(F21/F8,0) | G22: =IFERROR(G21/G8,0) | H22: =IFERROR(H21/H8,0)
B24: Money received | C24: =C8-C14-C17-C19-C21 | D24: =D8-D14-D17-D19-D21 | E24: =E8-E14-E17-E19-E21 | F24: =F8-F14-F17-F19-F21 | G24: =G8-G14-G17-G19-G21 | H24: =H8-H14-H17-H19-H21
C25: =IFERROR(C24/$C$8,0) | D25: =IFERROR(D24/$D$8,0) | E25: =IFERROR(E24/$E$8,0) | F25: =IFERROR(F24/$F$8,0) | G25: =IFERROR(G24/$G$8,0) | H25: =IFERROR(H24/$G$8,0)

Sheet Cashflow
A1: =Summary!B1 | K1: =H10+H8-H28 | M1: =H12*100/118
A2: Swiggy Cash Flow Statement - July 2025 | M2: =M1*0.02%
A4: S.No | B4: Details | C4: =Summary!C4 | D4: =Summary!D4 | E4: =Summary!E4 | F4: =Summary!F4 | G4: 27th to 31st | H4: Total
A5: 1 | B5: Item sales (Delivered orders) | C5: ='D1W1'!I2 | D5: ='D1W2'!I2 | E5: ='D1W3'!I2 | F5: ='D1W4'!I2 | G5: ='D1W5'!I2 | H5: =SUM(C5:G5)
B6: Add:- Packing charges | C6: ='D1W1'!J2 | D6: ='D1W2'!J2 | E6: ='D1W3'!J2 | F6: ='D1W4'!J2 | G6: ='D1W5'!J2 | H6: =SUM(C6:G6) | J6: GST | K6: =H10-H28
B7: Add:- Compensation paid for cancelled orders | C7: ='D1W1'!P1-'D1W1'!AG1 | D7: ='D1W2'!P1-'D1W2'!AG1 | E7: ='D1W3'!P1-'D1W3'!AG1 | F7: ='D1W4'!P1-'D1W4'!AG1 | G7: ='D1W5'!P1-'D1W5'!AG1 | H7: =SUM(C7:G7) | J7: TDS | K7: =H12*100/118
B8: Less:- Discount | C8: ='D1W1'!K2+'D1W1'!L2 | D8: ='D1W2'!K2+'D1W2'!L2 | E8: ='D1W3'!K2+'D1W3'!L2 | F8: ='D1W4'!K2+'D1W4'!L2 | G8: ='D1W5'!K2+'D1W5'!L2 | H8: =SUM(C8:G8)
B9: Add:- GST 5% | C9: ='D1W1'!O2 | D9: ='D1W2'!O2 | E9: ='D1W3'!O2 | F9: ='D1W4'!O2 | G9: ='D1W5'!O2 | H9: =SUM(C9:G9) | N9: =AVERAGE(J12:L12)
B10: Net Sales | C10: =C5+C6+C7-C8+C9 | D10: =D5+D6+D7-D8+D9 | E10: =E5+E6+E7-E8+E9 | F10: =F5+F6+F7-F8+F9 | G10: =G5+G6+G7-G8+G9 | H10: =SUM(C10:G10) | J10: =H10-H28
A11: 2 | B11: Less:- Commission | C11: =SUM(C12) | D11: =SUM(D12) | E11: =SUM(E12) | F11: =SUM(F12) | G11: =SUM(G12) | H11: =SUM(C11:G11)
B12: Platform Fee | C12: ='D1W1'!S3 | D12: ='D1W2'!S3 | E12: ='D1W3'!S3 | F12: ='D1W4'!S3 | G12: ='D1W5'!S3 | H12: =SUM(C12:G12) | J12: =C12/C10 | K12: =D12/D10 | L12: =E12/E10 | M12: =F12/F10 | N12: =AVERAGE(J12:M12)
A13: 3 | B13: Less:- Refunds | C13: =SUM(C14:C15) | D13: =SUM(D14:D15) | E13: =(E14+E15) | F13: =(F14+F15) | G13: =(G14+G15) | H13: =SUM(C13:G13)
B14: Paid by Restaurant | H14: =SUM(C14:G14)
B15: Received by Restaurant | C15: 0 | D15: 0 | E15: 0 | F15: 0 | G15: 0 | H15: =SUM(C15:G15) | J15: =C10+C8-C28 | K15: =D10+D8-D28 | L15: =E10+E8-E28 | M15: =F10+F8-F28 | N15: =G10+G8-G28
A16: 4 | B16: Less:- Marketing Charges | C16: =SUM(C17:C19) | D16: =SUM(D17:D19) | E16: =E17+E18+E19 | F16: =F17+F18+F19 | G16: =G17+G18+G19 | H16: =SUM(C16:G16) | J16: =C12*100/118 | K16: =D12*100/118 | L16: =E12*100/118 | M16: =F12*100/118 | N16: =G12*100/118
B17: High Priority | C17: =-'D2W1'!B13 | D17: =-'D2W2'!B14 | E17: =-'D2W3'!B14 | F17: =-'D2W4'!B9 | G17: =-'D2W5'!B8 | H17: =SUM(C17:G17) | J17: =J16*2% | K17: =K16*2% | L17: =L16*2% | M17: =M16*2% | N17: =N16*2%
B18: Call Center Service Fees | C18: ='D1W1'!Z3 | D18: ='D1W2'!Z3 | E18: ='D1W3'!Z3 | F18: ='D1W4'!Z3 | G18: ='D1W5'!Z3 | H18: =SUM(C18:G18)
B19: PocketHero Fee | C19: ='D1W1'!V3 | D19: ='D1W2'!V3 | E19: ='D1W3'!V3 | F19: ='D1W4'!V3 | G19: ='D1W5'!V3 | H19: =SUM(C19:G19)
A20: 5 | B20: Less:- Other Charges | C20: =SUM(C21:C23) | D20: =SUM(D21:D23) | E20: =E21+E22+E23 | F20: =F21+F22+F23 | G20: =G21+G22+G23 | H20: =SUM(C20:G20)
B21: Collection Charges | C21: ='D1W1'!X3 | D21: ='D1W2'!X3 | E21: ='D1W3'!X3 | F21: ='D1W4'!X3 | G21: ='D1W5'!X3 | H21: =SUM(C21:G21)
B22: Long Distance Fee | C22: ='D1W1'!T3 | D22: ='D1W2'!T3 | E22: ='D1W3'!T3 | F22: ='D1W4'!T3 | G22: ='D1W5'!T3 | H22: =SUM(C22:G22)
B23: Merchant Cancellation Charges | C23: ='D1W1'!Y3 | D23: ='D1W2'!Y3 | E23: ='D1W3'!Y3 | F23: ='D1W4'!Y3 | G23: ='D1W5'!Y3 | H23: =SUM(C23:G23)
B24: Profit from Swiggy | C24: =C5+C6+C7-C8+C9-C12-C13-C16-C20-C28 | D24: =D5+D6+D7-D8+D9-D12-D13-D16-D20-D28 | E24: =E5+E6+E7-E8+E9-E12-E13-E16-E20-E28 | F24: =F5+F6+F7-F8+F9-F12-F13-F16-F20-F28 | G24: =G5+G6+G7-G8+G9-G12-G13-G16-G20-G28 | H24: =SUM(C24:G24) | N24: 259885
A25: 6 | B25: Less:- Tax Adjustments | C25: =SUM(C26:C28) | D25: =SUM(D26:D28) | E25: =SUM(E26:E28) | F25: =SUM(F26:F28) | G25: =SUM(G26:G28) | H25: =SUM(C25:G25) | N25: 9643
B26: TDS deduction for aggrigators | C26: ='D1W1'!AJ4 | D26: ='D1W2'!AJ4 | E26: ='D1W3'!AJ4 | F26: ='D1W4'!AJ4 | G26: ='D1W5'!AJ4 | H26: =SUM(C26:G26)
B27: TCS | C27: ='D1W1'!AI4 | D27: ='D1W2'!AI4 | E27: ='D1W3'!AI4 | F27: ='D1W4'!AI4 | G27: ='D1W5'!AI4 | H27: =SUM(C27:G27) | N27: -23947.45
B28: GST collected and paid by swiggy | C28: ='D1W1'!AH4 | D28: ='D1W2'!AH4 | E28: ='D1W3'!AH4 | F28: ='D1W4'!AH4 | G28: ='D1W5'!AH4 | H28: =SUM(C28:G28) | N28: 12289.68
A29: 7 | B29: Expected Receipts | C29: =C24-C26 | D29: =D24-D26 | E29: =E24-E26 | F29: =F24-F26 | G29: =G24-G26 | H29: =SUM(C29:G29)
B30: Intriem payments | C30: 0 | D30: 0 | E30: 0 | F30: 0 | G30: 0 | H30: 0
B31: EMI Loan deductions | C31: 0 | D31: 0 | E31: 0 | F31: 0 | G31: 0 | H31: =SUM(C31:G31)
B32: Actual receipts | G32: =BANK!G2 | H32: =SUM(C32:G32)
A33: 8 | B33: Difference | C33: =C29-C30-C31-C32 | D33: =D29-D30-D31-D32 | E33: =E29-E30-E31-E32 | F33: =F29-F30-F31-F32 | G33: =G29-G30-G31-G32 | H33: =SUM(C33:G33)
B35: Notes:-
B36: 1. Last week bank credits will be credited in the next month.

Sheet BANK
C1: 1 | D1: 2 | E1: 3 | F1: 4 | G1: 5
B2: swiggy | C2: 21505.95 | D2: 30781.79 | E2: 30342.24 | F2: 38669.62
A10: Date | B10: Narration | C10: Chq./Ref.No. | D10: Value Dt | E10: Withdrawal Amt. | F10: Deposit Amt. | G10: Closing Balance
A11: 01/07/25 | B11: NEFT CR-YESB0000001-ONE 97 COMMUNICATIONS LIMITED SETTL-ROCKTAIL HOSPITALITY SERVICES-YESBN12025070104207251 | C11: YESBN12025070104207251 | D11: 01/07/25 | F11: 27641 | G11: 575581.24
A12: 01/07/25 | B12: NEFT CR-RATN0000999-PINELABS PVT LTD-ROCKTAIL HOSPITALITY SERVICES-RATNN52025070127611676 | C12: RATNN52025070127611676 | D12: 01/07/25 | F12: 1509.75 | G12: 577090.99
A13: 01/07/25 | B13: 42552392TERMINAL 1 CARDS SETTL. 01/07/25 | C13: 000000000000000 | D13: 01/07/25 | F13: 2521.73 | G13: 579612.72
A14: 01/07/25 | B14: GST/BANK REFERENCE NO: R2518264868104/CIN NO: HDFC25073600001570 | C14: 0250701360001319 | D14: 01/07/25 | E14: 108078 | G14: 471534.72
A15: 01/07/25 | B15: NEFT CR-YESB0000001-SWIGGY LIMITED-ROCKTAIL HOSPITALITY SERVICES-YESBN12025070105744412 | C15: YESBN12025070105744412 | D15: 01/07/25 | F15: 70187.2 | G15: 541721.92
A16: 02/07/25 | B16: NEFT CR-YESB0000001-ONE 97 COMMUNICATIONS LIMITED SETTL-ROCKTAIL HOSPITALITY SERVICES-YESBN12025070202489683 | C16: YESBN12025070202489683 | D16: 02/07/25 | F16: 32140.42 | G16: 573862.34
A17: 02/07/25 | B17: 42552392TERMINAL 1 CARDS SETTL. 02/07/25 | C17: 000000000000000 | D17: 02/07/25 | F17: 2252.65 | G17: 576114.99
A18: 02/07/25 | B18: 42552394TERMINAL 1 CARDS SETTL. 02/07/25 | C18: 000000000000000 | D18: 02/07/25 | F18: 556.76 | G18: 576671.75
A19: 02/07/25 | B19: NEFT CR-CITI0000002-ETERNAL LIMITED-ROCKTAIL HOSPITALITY SERVICES-CITIN52025070288932874 | C19: CITIN52025070288932874 | D19: 02/07/25 | F19: 47888.79 | G19: 624560.54
A20: 02/07/25 | B20: UPI-AGROMECH INDUSTRIES-BAJAJPAY.6879729.02771144@INDUS-INDB0MERCHA-107417334493-DOSA EQUIPMENT ADV | C20: 0000107417334493 | D20: 02/07/25 | E20: 30000 | G20: 594560.54
A21: 03/07/25 | B21: NEFT CR-YESB0000001-ONE 97 COMMUNICATIONS LIMITED SETTL-ROCKTAIL HOSPITALITY SERVICES-YESBN12025070301800334 | C21: YESBN12025070301800334 | D21: 03/07/25 | F21: 20179.42 | G21: 614739.96
A22: 03/07/25 | B22: 42552392TERMINAL 1 CARDS SETTL. 03/07/25 | C22: 000000000000000 | D22: 03/07/25 | F22: 8653.95 | G22: 623393.91
A23: 04/07/25 | B23: NEFT CR-YESB0000001-ONE 97 COMMUNICATIONS LIMITED SETTL-ROCKTAIL HOSPITALITY SERVICES-YESBN12025070403786865 | C23: YESBN12025070403786865 | D23: 04/07/25 | F23: 31048.13 | G23: 654442.04
A24: 04/07/25 | B24: 42552394TERMINAL 1 CARDS SETTL. 04/07/25 | C24: 000000000000000 | D24: 04/07/25 | F24: 4251.24 | G24: 658693.28
A25: 04/07/25 | B25: NEFT CR-YESB0000001-SWIGGY LIMITED-ROCKTAIL HOSPITALITY SERVICES-YESBN12025070405363208 | C25: YESBN12025070405363208 | D25: 04/07/25 | F25: 21022.24 | G25: 679715.52
A26: 04/07/25 | B26: NEFT CR-UTIB0000052-BUNDL TECHNOLOGIES PRIVATE LIMITED-ROCKTAIL HOSPITALITY SERVICES-UTIBN62025070410121377 | C26: UTIBN62025070410121377 | D26: 04/07/25 | F26: 46137.34 | G26: 725852.86
A27: 04/07/25 | B27: UPI-ZOMATO ONLINE ORDER-ZOMATOONLINEORD384743.RZP@RXAIRTEL-AIRP0000011-107550400754-ZOMATOONLINEORDER | C27: 0000107550400754 | D27: 04/07/25 | E27: 2589.1 | G27: 723263.76
A28: 04/07/25 | B28: UPI-ZOMATO ONLINE ORDER-ZOMATOONLINEORD384743.RZP@RXAIRTEL-AIRP0000011-107550521516-ZOMATOONLINEORDER | C28: 0000107550521516 | D28: 05/07/25 | E28: 2589.1 | G28: 720674.66
A29: 05/07/25 | B29: NEFT CR-YESB0000001-ONE 97 COMMUNICATIONS LIMITED SETTL-ROCKTAIL HOSPITALITY SERVICES-YESBN12025070503391886 | C29: YESBN12025070503391886 | D29: 05/07/25 | F29: 53539.04 | G29: 774213.7
A30: 05/07/25 | B30: 42552392TERMINAL 1 CARDS SETTL. 05/07/25 | C30: 000000000000000 | D30: 05/07/25 | F30: 3251.71 | G30: 777465.41
A31: 05/07/25 | B31: SETTLEMENT CHARGE-JUN25-CPY594 | C31: 000000000000000 | D31: 05/07/25 | E31: 30.68 | G31: 777434.73
A32: 05/07/25 | B32: SETTLEMENT CHARGE-JUN25-CPY597 | C32: 000000000000000 | D32: 05/07/25 | E32: 25.96 | G32: 777408.77
A33: 06/07/25 | B33: NEFT CR-YESB0000001-ONE 97 COMMUNICATIONS LIMITED SETTL-ROCKTAIL HOSPITALITY SERVICES-YESBN12025070603478046 | C33: YESBN12025070603478046 | D33: 06/07/25 | F33: 79401.62 | G33: 856810.39
A34: 06/07/25 | B34: EMI 162047443 CHQ S16204744311 0725162047443 | C34: 000000000000000 | D34: 06/07/25 | E34: 70666 | G34: 786144.39
A35: 06/07/25 | B35: 42552392TERMINAL 1 CARDS SETTL. 06/07/25 | C35: 000000000000000 | D35: 06/07/25 | F35: 7572.79 | G35: 793717.18
A36: 06/07/25 | B36: 42552394TERMINAL 1 CARDS SETTL. 06/07/25 | C36: 000000000000000 | D36: 06/07/25 | F36: 10604.11 | G36: 804321.29
A37: 06/07/25 | B37: UPI-WOLFFPACK VENTURES P-ABHISHEK.LADHA11-1@OKHDFCBANK-HDFC0000512-107618941469-LOAN EMI | C37: 0000107618941469 | D37: 06/07/25 | F37: 35333 | G37: 839654.29
A38: 06/07/25 | B38: UPI-HARISH RAGHAVENDRA-HARISH.RAGHAVENDRA26@OKHDFCBANK-ICIC0000069-245979904572-PIZZA STONE | C38: 0000245979904572 | D38: 06/07/25 | E38: 10000 | G38: 829654.29
A39: 06/07/25 | B39: UPI-RAZORPAY-PG.RAZORPAY@AXISBANK-UTIB0001506-321362241875-ZOMATOOREFUNDQP553 | C39: 0000321362241875 | D39: 06/07/25 | F39: 2589.1 | G39: 832243.39
A40: 07/07/25 | B40: NEFT CR-YESB0000001-ONE 97 COMMUNICATIONS LIMITED SETTL-ROCKTAIL HOSPITALITY SERVICES-YESBN12025070703506891 | C40: YESBN12025070703506891 | D40: 07/07/25 | F40: 68500.38 | G40: 900743.77
A41: 07/07/25 | B41: 42552392TERMINAL 1 CARDS SETTL. 07/07/25 | C41: 000000000000000 | D41: 07/07/25 | F41: 6448.08 | G41: 907191.85
A42: 07/07/25 | B42: 42552394TERMINAL 1 CARDS SETTL. 07/07/25 | C42: 000000000000000 | D42: 07/07/25 | F42: 6613.36 | G42: 913805.21
A43: 07/07/25 | B43: NEFT CR-CITI0000002-ETERNAL LIMITED-ROCKTAIL HOSPITALITY SERVICES-CITIN52025070790533046 | C43: CITIN52025070790533046 | D43: 07/07/25 | F43: 54165.64 | G43: 967970.85
A44: 07/07/25 | B44: UPI-GADDAM NIRANJAN-G.NIRANJANNANI-1@OKAXIS-UTIB0000027-107702908442-UPI | C44: 0000107702908442 | D44: 07/07/25 | E44: 500 | G44: 967470.85
A45: 08/07/25 | B45: NEFT CR-YESB0000001-ONE 97 COMMUNICATIONS LIMITED SETTL-ROCKTAIL HOSPITALITY SERVICES-YESBN12025070802852556 | C45: YESBN12025070802852556 | D45: 08/07/25 | F45: 29438 | G45: 996908.85
A46: 08/07/25 | B46: NEFT CR-SCBL0036001-AMERICAN EXPRESS BANKING CORP-ROCKTAIL HOSPITALITY SERVICES-SCBLN52025070800525663 | C46: SCBLN52025070800525663 | D46: 08/07/25 | F46: 968.25 | G46: 997877.1
A47: 08/07/25 | B47: 42552394TERMINAL 1 CARDS SETTL. 08/07/25 | C47: 000000000000000 | D47: 08/07/25 | F47: 5211.01 | G47: 1003088.1
...

Sheet Profit statement
B1: =Summary!B1
B2: Swiggy Profit Statement - July 2025
B4: Details | C4: =Cashflow!C4 | D4: =Cashflow!D4 | E4: =Cashflow!E4 | F4: =Cashflow!F4 | G4: =Summary!G4 | H4: Total
B5: A. Net Sales
B6: Total Income | C6: =Cashflow!C5+Cashflow!C6-Cashflow!C8+Cashflow!C9-Cashflow!C28 | D6: =Cashflow!D5+Cashflow!D6-Cashflow!D8+Cashflow!D9-Cashflow!D28 | E6: =Cashflow!E5+Cashflow!E6-Cashflow!E8+Cashflow!E9-Cashflow!E28 | F6: =Cashflow!F5+Cashflow!F6-Cashflow!F8+Cashflow!F9-Cashflow!F28 | G6: =Cashflow!G5+Cashflow!G6-Cashflow!G8+Cashflow!G9-Cashflow!G28 | H6: =SUM(C6:G6)
B7: Add- Adjust: Cancelled orders (By Swiggy) | C7: =Cashflow!C7 | D7: 0 | E7: =Cashflow!E7 | F7: =Cashflow!F7 | G7: =Cashflow!G7 | H7: =SUM(C7:G7)
B8: Net Sales (Number that you see on Numerize app) | C8: =C6+C7 | D8: =D6+D7 | E8: =E6+E7 | F8: =F6+F7 | G8: =G6+G7 | H8: =H6+H7
B10: B. Less:- Commission | C10: =Cashflow!C11 | D10: =Cashflow!D11 | E10: =Cashflow!E11 | F10: =Cashflow!F11 | G10: =Cashflow!G11 | H10: =SUM(C10:G10)
B12: C. Less:- Marketing & Ads | C12: =Cashflow!C16 | D12: =Cashflow!D16 | E12: =Cashflow!E16 | F12: =Cashflow!F16 | G12: =Cashflow!G16 | H12: =SUM(C12:G12)
B14: D. Less:- Refund on disputed orders | C14: =Cashflow!C13 | D14: =Cashflow!D13 | E14: =Cashflow!E13 | F14: =Cashflow!F13 | G14: =Cashflow!G13 | H14: =SUM(C14:G14)
B16: E. Other charges | C16: =Cashflow!C20 | D16: =Cashflow!D20 | E16: =Cashflow!E20 | F16: =Cashflow!F20 | G16: =Cashflow!G20 | H16: =SUM(C16:G16)
B18: F. Profit | C18: =C8-C10-C12-C14-C16 | D18: =D8-D10-D12-D14-D16 | E18: =E8-E10-E12-E14-E16 | F18: =F8-F10-F12-F14-F16 | G18: =G8-G10-G12-G14-G16 | H18: =H8-H10-H12-H14-H16
B19: Percentage | C19: =C18/C8 | D19: =D18/D8 | E19: =IFERROR(E18/E8,0) | F19: =IFERROR(F18/F8,0) | G19: =IFERROR(G18/G8,0) | H19: =H18/H8

Sheet Discrepancies
B1: =Summary!B1
B2: Swiggy Discrepancies - July 2025
B4: Details | C4: =Summary!C4 | D4: =Summary!D4 | E4: =Summary!E4 | F4: =Summary!F4 | G4: =Summary!G4 | H4: Total
B5: A. POS discrepancies
B6: Sales as per Swiggy | C6: =Cashflow!C10 | D6: =Cashflow!D10 | E6: =Cashflow!E10 | F6: =Cashflow!F10 | G6: =Cashflow!G10 | H6: =SUM(C6:G6)
B7: Sale as per POS | H7: =SUM(C7:G7)
B8: Difference | C8: =C6-C7 | D8: =D6-D7 | E8: =E6-E7 | F8: =F6-F7 | G8: =G6-G7 | H8: =SUM(C8:G8)
C9: =IFERROR(C8/C6,0) | D9: =IFERROR(D8/D6,0) | E9: =IFERROR(E8/E6,0) | F9: =IFERROR(F8/F6,0) | G9: =IFERROR(G8/G6,0) | H9: =IFERROR(H8/H6,0)
B11: B. Order discrepancies
B12: No.of delivered orders for which payment isn't received | C12: 0 | D12: 0 | E12: 0 | F12: 0 | G12: 0 | H12: =SUM(C12:G12)
B13: Value of such orders | C13: 0 | D13: 0 | E13: 0 | F13: 0 | G13: 0 | H13: =SUM(C13:G13)
B16: C. Payment discrepancies
B17: Expected receipts in the bank account | C17: =Cashflow!C29 | D17: =Cashflow!D29 | E17: =Cashflow!E29 | F17: =Cashflow!F29 | G17: =Cashflow!G29 | H17: =SUM(C17:G17)
B18: Interim Payments | C18: 0 | D18: 0 | E18: 0 | F18: 0 | G18: 0 | H18: =SUM(C18:G18)
B19: Actual receipts in the bank | H19: =SUM(C19:G19)
B20: Difference | C20: =C17-C19-C18 | D20: =D17-D19-D18 | E20: =E17-E19-E18 | F20: =F17-F19-F18 | G20: =G17-G19-G18 | H20: =H17-H19-H18
B22: Notes:
B23: 1. Last week bank credits will be credited in the next month.
B24: 2. There is difference between POS and actual sales, 208.43/- is less in POS

Sheet POS
G1: Week 1 | H1: Week 2 | I1: Week 3 | J1: Week 4 | K1: Week 5
G2: 34088 | H2: 46933 | I2: 48536 | J2: 62572 | K2: 31390
N8: {=SUBTOTAL(9,N10:N2235)}
A9: Invoice No. | B9: Date | C9: Payment Type | D9: Order Type | E9: Status | F9: Persons | G9: Area | H9: Assign To | I9: Cash | J9: Card | K9: Due Payment | L9: Other | M9: Wallet | N9: Online
A10: 86857 | B10: 45870 | C10: Cash | D10: Dine In | E10: Success | G10: Dine in | H10: Pavan | I10: 372 | J10: 0 | K10: 0 | L10: 0 | M10: 0 | N10: 0
A11: 86856 | B11: 45870 | C11: Other [Swiggy Dineout] | D11: Dine In | E11: Success | G11: Dine in | H11: Pavan | I11: 0 | J11: 0 | K11: 0 | L11: 2105 | M11: 0 | N11: 0
A12: 86855 | B12: 45870 | C12: Cash | D12: Dine In | E12: Success | F12: 2 | G12: Dine in | H12: Prashant | I12: 1009 | J12: 0 | K12: 0 | L12: 0 | M12: 0 | N12: 0
A13: 86854 | B13: 45870 | C13: Other [upi] | D13: Dine In | E13: Success | F13: 3 | G13: Dine in | H13: Prashant | I13: 0 | J13: 0 | K13: 0 | L13: 1678 | M13: 0 | N13: 0
A14: 86853 | B14: 45870 | C14: Other [upi] | D14: Dine In | E14: Success | G14: Dine in | H14: Pavan | I14: 0 | J14: 0 | K14: 0 | L14: 2272 | M14: 0 | N14: 0
A15: 86852 | B15: 45870 | C15: CARD | D15: Dine In | E15: Success | G15: Dine in | H15: Prashant | I15: 0 | J15: 1010 | K15: 0 | L15: 0 | M15: 0 | N15: 0
A16: 86851 | B16: 45870 | C16: Other [Swiggy Dineout] | D16: Dine In | E16: Success | F16: 3 | G16: Dine in | H16: Prashant | I16: 0 | J16: 0 | K16: 0 | L16: 1844 | M16: 0 | N16: 0
A17: 86850 | B17: 45870 | C17: Other [upi] | D17: Dine In | E17: Success | G17: Dine in | H17: Pavan | I17: 0 | J17: 0 | K17: 0 | L17: 120 | M17: 0 | N17: 0
A18: 86849 | B18: 45870 | C18: Other [Zomato Gold] | D18: Dine In | E18: Success | F18: 3 | G18: Dine in | H18: Pavan | I18: 0 | J18: 0 | K18: 0 | L18: 2687 | M18: 0 | N18: 0
A19: 86848 | B19: 45870 | C19: Other [Swiggy Dineout] | D19: Dine In | E19: Success | F19: 2 | G19: Dine in | H19: Prashant | I19: 0 | J19: 0 | K19: 0 | L19: 1525 | M19: 0 | N19: 0
A20: 86847 | B20: 45870 | C20: Other [upi] | D20: Dine In | E20: Success | G20: Dine in | H20: Prashant | I20: 0 | J20: 0 | K20: 0 | L20: 460 | M20: 0 | N20: 0
A21: 86846 | B21: 45870 | C21: Other [Zomato Gold] | D21: Dine In | E21: Success | G21: Dine in | H21: Pavan | I21: 0 | J21: 0 | K21: 0 | L21: 987 | M21: 0 | N21: 0
A22: 86845 | B22: 45870 | C22: Other [upi] | D22: Dine In | E22: Success | G22: Dine in | H22: Pavan | I22: 0 | J22: 0 | K22: 0 | L22: 307 | M22: 0 | N22: 0
A23: 86844 | B23: 45870 | C23: Other [Swiggy Dineout] | D23: Dine In | E23: Success | G23: Dine in | I23: 0 | J23: 0 | K23: 0 | L23: 2830 | M23: 0 | N23: 0
A24: 86843 | B24: 45870 | C24: Other [Zomato Gold] | D24: Dine In | E24: Success | F24: 4 | G24: Dine in | H24: Prashant | I24: 0 | J24: 0 | K24: 0 | L24: 2840 | M24: 0 | N24: 0
A25: 86842 | B25: 45870 | C25: Other [Zomato Gold] | D25: Dine In | E25: Success | G25: Dine in | H25: Prashant | I25: 0 | J25: 0 | K25: 0 | L25: 1535 | M25: 0 | N25: 0
A26: 86841 | B26: 45870 | C26: Other [Zomato Gold] | D26: Dine In | E26: Success | F26: 3 | G26: Dine in | H26: Prashant | I26: 0 | J26: 0 | K26: 0 | L26: 2390 | M26: 0 | N26: 0
A27: 86840 | B27: 45870 | C27: CARD | D27: Dine In | E27: Success | G27: Dine in | H27: This is It | I27: 0 | J27: 1547 | K27: 0 | L27: 0 | M27: 0 | N27: 0
A28: 86839 | B28: 45870 | C28: Other [Zomato Gold] | D28: Dine In | E28: Success | G28: Dine in | H28: Pavan | I28: 0 | J28: 0 | K28: 0 | L28: 1062 | M28: 0 | N28: 0
A29: 86838 | B29: 45870 | C29: Online | D29: Delivery(Parcel) | E29: Success | G29: Zomato | I29: 0 | J29: 0 | K29: 0 | L29: 0 | M29: 0 | N29: 784
A30: 86837 | B30: 45870 | C30: Other [upi] | D30: Dine In | E30: Success | G30: Dine in | H30: Prashant | I30: 0 | J30: 0 | K30: 0 | L30: 920 | M30: 0 | N30: 0
A31: 86836 | B31: 45870 | C31: Other [upi] | D31: Dine In | E31: Success | F31: 3 | G31: Dine in | H31: Prashant | I31: 0 | J31: 0 | K31: 0 | L31: 1064 | M31: 0 | N31: 0
A32: 86835 | B32: 45870 | C32: Online | D32: Delivery(Parcel) | E32: Success | G32: Swiggy_This is it Cafe | I32: 0 | J32: 0 | K32: 0 | L32: 0 | M32: 0 | N32: 403
A33: 86834 | B33: 45870 | C33: Other [upi] | D33: Dine In | E33: Success | F33: 4 | G33: Dine in | H33: Prashant | I33: 0 | J33: 0 | K33: 0 | L33: 1591 | M33: 0 | N33: 0
A34: 86833 | B34: 45870 | C34: Online | D34: Delivery(Parcel) | E34: Success | G34: Zomato | I34: 0 | J34: 0 | K34: 0 | L34: 0 | M34: 0 | N34: 980
A35: 86832 | B35: 45870 | C35: Online | D35: Delivery(Parcel) | E35: Success | G35: Zomato | I35: 0 | J35: 0 | K35: 0 | L35: 0 | M35: 0 | N35: 188
A36: 86831 | B36: 45870 | C36: Other [Swiggy Dineout] | D36: Dine In | E36: Success | G36: Dine in | H36: Pavan | I36: 0 | J36: 0 | K36: 0 | L36: 1393 | M36: 0 | N36: 0
A37: 86830 | B37: 45870 | C37: Other [upi] | D37: Dine In | E37: Success | G37: Dine in | H37: Pavan | I37: 0 | J37: 0 | K37: 0 | L37: 438 | M37: 0 | N37: 0
A38: 86829 | B38: 45870 | C38: CARD | D38: Dine In | E38: Success | F38: 2 | G38: Dine in | H38: Prashant | I38: 0 | J38: 2460 | K38: 0 | L38: 0 | M38: 0 | N38: 0
A39: 86828 | B39: 45870 | C39: Cash | D39: Dine In | E39: Success | G39: Dine in | H39: Pavan | I39: 900 | J39: 0 | K39: 0 | L39: 0 | M39: 0 | N39: 0
A40: 86827 | B40: 45870 | C40: Online | D40: Delivery(Parcel) | E40: Success | G40: Zomato | I40: 0 | J40: 0 | K40: 0 | L40: 0 | M40: 0 | N40: 775
A41: 86826 | B41: 45870 | C41: Other [upi] | D41: Dine In | E41: Success | G41: Dine in | H41: Pavan | I41: 0 | J41: 0 | K41: 0 | L41: 274 | M41: 0 | N41: 0
A42: 86825 | B42: 45870 | C42: Other [Zomato Gold] | D42: Dine In | E42: Success | G42: Dine in | H42: Pavan | I42: 0 | J42: 0 | K42: 0 | L42: 1393 | M42: 0 | N42: 0
A43: 86824 | B43: 45870 | C43: Other [upi] | D43: Dine In | E43: Success | G43: Dine in | H43: This is It | I43: 0 | J43: 0 | K43: 0 | L43: 669 | M43: 0 | N43: 0
A44: 86823 | B44: 45870 | C44: Online | D44: Delivery(Parcel) | E44: Success | G44: Zomato | I44: 0 | J44: 0 | K44: 0 | L44: 0 | M44: 0 | N44: 701
A45: 86822 | B45: 45870 | C45: Other [upi] | D45: Dine In | E45: Success | G45: Dine in | H45: Pavan | I45: 0 | J45: 0 | K45: 0 | L45: 723 | M45: 0 | N45: 0
...

Sheet D1W1
I1: 1525 | J1: 59 | K1: 99.98 | L1: 0 | M1: 99.98 | N1: 1484.02 | O1: 74.2 | P1: 1558.216 | Q1: 1343.17 | R1: 0 | S1: 278.29 | T1: 0 | U1: 0 | V1: 0 | W1: 0 | X1: 0 | Y1: 0 | Z1: 0 | AA1: 0 | AB1: 0 | AC1: 50.08 | AD1: 328.37 | AE1: 215.04 | AF1: 0 | AG1: 215.04 | AH1: 63.96 | AI1: 0 | AJ1: 1.28 | AK1: 65.24 | AL1: 949.55 | AM1: 0 | AN1: 17.762 | AO1: 0 | AP1: 0 | AQ1: 0 | AR1: 0 | AS1: 0 | AT1: 0 | AU1: 157.33333 | AV1: 0 | AW1: 0 | AX1: 0 | AY1: 0 | AZ1: 0 | BA1: 0 | BB1: 0 | BC1: 0 | BD1: 0 | BE1: 0 | BF1: 0 | BG1: 0 | BH1: 0 | BI1: 0 | BJ1: 0 | BK1: 0 | BL1: 0 | BM1: 0 | BN1: 0 | BO1: 0 | BP1: 0 | BQ1: 0 | BR1: 0 | BS1: 0 | BT1: 0 | BU1: 0 | BV1: 0 | BW1: 0 | BX1: 0 | BY1: 0 | BZ1: 0 | CA1: 0 | CB1: 0 | CC1: 0
I2: 923695 | J2: 33137 | K2: 92340.33 | L2: 362.77 | M2: 92703.1 | N2: 864128.9 | O2: 43209.86 | P2: 907338.15 | Q2: 907337.72 | R2: 0 | S2: 156286.91 | T2: 3955 | U2: 0 | V2: 0 | W2: 0 | X2: 0 | Y2: 0 | Z2: 0 | AA2: 0 | AB2: 0 | AC2: 28841.84 | AD2: 189083.75 | AE2: 0 | AF2: 415 | AG2: 415 | AH2: 43206.34 | AI2: 0 | AJ2: 866.25 | AK2: 44072.59 | AL2: 673761.45 | AM2: 0 | AN2: 5900.627 | AO2: 0 | AP2: 0 | AQ2: 0 | AR2: 0 | AS2: 0 | AT2: 0 | AU2: 0 | AV2: 0 | AW2: 0 | AX2: 0 | AY2: 0 | AZ2: 0 | BA2: 0 | BB2: 0 | BC2: 0 | BD2: 0 | BE2: 0 | BF2: 0 | BG2: 0 | BH2: 0 | BI2: 0 | BJ2: 0 | BK2: 0 | BL2: 0 | BM2: 0 | BN2: 0 | BO2: 0 | BP2: 0 | BQ2: 0 | BR2: 0 | BS2: 0 | BT2: 0 | BU2: 0 | BV2: 0 | BW2: 0 | BX2: 0 | BY2: 0 | BZ2: 0 | CA2: 0 | CB2: 0 | CC2: 0
I3: 1091759.6 | J3: 39171.28 | K3: 109079.57 | L3: 428.0686 | M3: 109507.63 | N3: 1021423.2 | O3: 51075.191 | P3: 1072497.7 | Q3: 1072243.5 | R3: 0 | S3: 184746.94 | T3: 4666.9 | U3: 0 | V3: 0 | W3: 0 | X3: 0 | Y3: 0 | Z3: 0 | AA3: 0 | AB3: 0 | AC3: 34092.466 | AD3: 223506.3 | AE3: 253.7472 | AF3: 489.7 | AG3: 743.4472 | AH3: 51058.954 | AI3: 0 | AJ3: 1023.6854 | AK3: 52082.639 | AL3: 796158.98 | AM3: 0 | AN3: 6983.699 | AO3: 0 | AP3: 0 | AQ3: 0 | AR3: 0 | AS3: 0 | AT3: 0 | AU3: 185.65333 | AV3: 0 | AW3: 0 | AX3: 0 | AY3: 0 | AZ3: 0 | BA3: 0 | BB3: 0 | BC3: 0 | BD3: 0 | BE3: 0 | BF3: 0 | BG3: 0 | BH3: 0 | BI3: 0 | BJ3: 0 | BK3: 0 | BL3: 0 | BM3: 0 | BN3: 0 | BO3: 0 | BP3: 0 | BQ3: 0 | BR3: 0 | BS3: 0 | BT3: 0 | BU3: 0 | BV3: 0 | BW3: 0 | BX3: 0 | BY3: 0 | BZ3: 0 | CA3: 0 | CB3: 0 | CC3: 0
I4: 925220 | J4: 33196 | K4: 92440.31 | L4: 362.77 | M4: 92803.08 | N4: 865612.92 | O4: 43284.06 | P4: 908896.36 | Q4: 908680.89 | R4: 0 | S4: 156565.2 | T4: 3955 | U4: 0 | V4: 0 | W4: 0 | X4: 0 | Y4: 0 | Z4: 0 | AA4: 0 | AB4: 0 | AC4: 28891.92 | AD4: 189412.12 | AE4: 215.04 | AF4: 415 | AG4: 630.04 | AH4: 43270.3 | AI4: 0 | AJ4: 867.53 | AK4: 44137.83 | AL4: 674711 | AM4: 0 | AN4: 5918.389 | AO4: 0 | AP4: 0 | AQ4: 0 | AR4: 0 | AS4: 0 | AT4: 0 | AU4: 157.33333 | AV4: 0 | AW4: 0 | AX4: 0 | AY4: 0 | AZ4: 0 | BA4: 0 | BB4: 0 | BC4: 0 | BD4: 0 | BE4: 0 | BF4: 0 | BG4: 0 | BH4: 0 | BI4: 0 | BJ4: 0 | BK4: 0 | BL4: 0 | BM4: 0 | BN4: 0 | BO4: 0 | BP4: 0 | BQ4: 0 | BR4: 0 | BS4: 0 | BT4: 0 | BU4: 0 | BV4: 0 | BW4: 0 | BX4: 0 | BY4: 0 | BZ4: 0 | CA4: 0 | CB4: 0 | CC4: 0
A5: Order ID | B5: Parent Order ID | C5: Order Date | D5: Order Status | E5: Order Category | F5: Order Payment Type | G5: Cancelled By? | H5: Coupon type applied by customer | I5: Item Total | J5: Packaging Charges | K5: Restaurant Discounts (Promo, Freebies, Flat Off, etc.) | L5: Swiggy One Exclusive Offer Discount | M5: Restaurant Discount Share [3a+3b] | N5: Net Bill Value (before taxes) [1+2-3] | O5: GST Collected | P5: Total Customer Paid [4+5] | Q5: Commission charged on | R5: Service Fees % | S5: Commission | T5: Long Distance Charges | U5: Discount on Long Distance Fee | V5: Pocket Hero Fees | W5: Swiggy One Fees | X5: Payment Collection Charges | Y5: Restaurant Cancellation Charges | Z5: Call Center Charges | AA5: Delivery Fee sponsored by Restaurant (w/o tax) | AB5: Bolt Fees | AC5: GST on Service Fee @18% | AD5: Total Swiggy Fees [6+7+8-9+10+11+12+13+14+15+16] | AE5: Customer Cancellations | AF5: Customer Complaints | AG5: Complaint & Cancellation Charges [17+18] | AH5: GST Deduction | AI5: TCS | AJ5: TDS | AK5: Total Taxes [19+20+21] | AL5: Net Payout for Order (after taxes) [A-B-C-D] | AM5: Long Distance Order | AN5: Last Mile (in km) | AO5: MFR Accurate? | AP5: MFR Pressed? | AQ5: Coupon Code Sourced | AR5: Discount Campaign ID | AS5: Replicated Order | AT5: Base order ID | AU5: Cancellation time | AV5: Pick Up Status | AW5: Swiggy One Customer? | AX5: Pocket Hero Order?
A6: 215677732890652 | C6: 2025-09-01 11:58:52 | D6: delivered | E6: regular | I6: 160 | J6: 14 | K6: 0 | L6: 0 | M6: 0 | N6: 174 | O6: 8.7 | P6: 182.7 | Q6: 182.7 | R6: 22.0% | S6: 40.19 | T6: 0 | U6: 0 | V6: 0 | W6: 0 | X6: 0 | Y6: 0 | Z6: 0 | AA6: 0 | AB6: 0 | AC6: 7.24 | AD6: 47.43 | AE6: 0 | AF6: 0 | AG6: 0 | AH6: 8.7 | AI6: 0 | AJ6: 0.17 | AK6: 8.87 | AL6: 126.41 | AM6: No | AN6: 2.741 | AO6: Yes | AP6: No | AR6: 206500dc-ba9e-4a58-be62-bb3f830ec1f3 | AS6: No | AW6: Yes | AX6: No
A7: 215677963601856 | C7: 2025-09-01 12:02:43 | D7: delivered | E7: regular | H7: FLAVORFUL | I7: 1070 | J7: 35 | K7: 99.99 | L7: 0 | M7: 99.99 | N7: 1005.01 | O7: 50.26 | P7: 1055.268 | Q7: 1055.27 | R7: 16.0% | S7: 168.84 | T7: 0 | U7: 0 | V7: 0 | W7: 0 | X7: 0 | Y7: 0 | Z7: 0 | AA7: 0 | AB7: 0 | AC7: 30.4 | AD7: 199.24 | AE7: 0 | AF7: 0 | AG7: 0 | AH7: 50.25 | AI7: 0 | AJ7: 1.01 | AK7: 51.26 | AL7: 804.78 | AM7: No | AN7: 3.139 | AO7: Yes | AP7: No | AR7: ac0e42c3-a3b6-4eba-95c9-97e2a420b3c7,206500dc-ba9e-4a58-be62-bb3f830ec1f3,ac0e42c3-a3b6-4eba-95c9-97e2a420b3c7,206500dc-ba9e-4a58-be62-bb3f830ec1f3 | AS7: No | AW7: Yes | AX7: No
A8: 215678197728179 | C8: 2025-09-01 12:06:37 | D8: delivered | E8: regular | H8: SWIGGYIT | I8: 495 | J8: 20 | K8: 64 | L8: 0 | M8: 64 | N8: 451 | O8: 22.56 | P8: 473.56 | Q8: 473.56 | R8: 22.0% | S8: 104.18 | T8: 12 | U8: 0 | V8: 0 | W8: 0 | X8: 0 | Y8: 0 | Z8: 0 | AA8: 0 | AB8: 0 | AC8: 20.92 | AD8: 137.1 | AE8: 0 | AF8: 0 | AG8: 0 | AH8: 22.55 | AI8: 0 | AJ8: 0.45 | AK8: 23 | AL8: 313.47 | AM8: Yes | AN8: 8.596 | AO8: Yes | AP8: No | AR8: 100833489 | AS8: No | AW8: Yes | AX8: No
A9: 215678342271988 | C9: 2025-09-01 12:09:02 | D9: delivered | E9: regular | I9: 950 | J9: 30 | K9: 0 | L9: 0 | M9: 0 | N9: 980 | O9: 49 | P9: 1029 | Q9: 1029 | R9: 16.0% | S9: 164.64 | T9: 0 | U9: 0 | V9: 0 | W9: 0 | X9: 0 | Y9: 0 | Z9: 0 | AA9: 0 | AB9: 0 | AC9: 29.64 | AD9: 194.28 | AE9: 0 | AF9: 0 | AG9: 0 | AH9: 49 | AI9: 0 | AJ9: 0.98 | AK9: 49.98 | AL9: 784.74 | AM9: No | AN9: 2.541 | AO9: Yes | AP9: No | AR9: 206500dc-ba9e-4a58-be62-bb3f830ec1f3 | AS9: No | AW9: Yes | AX9: No
A10: 215678409572245 | C10: 2025-09-01 12:10:09 | D10: delivered | E10: regular | I10: 295 | J10: 15 | K10: 0 | L10: 0 | M10: 0 | N10: 310 | O10: 15.5 | P10: 325.5 | Q10: 325.5 | R10: 22.0% | S10: 71.61 | T10: 0 | U10: 0 | V10: 0 | W10: 0 | X10: 0 | Y10: 0 | Z10: 0 | AA10: 0 | AB10: 0 | AC10: 12.88 | AD10: 84.49 | AE10: 0 | AF10: 0 | AG10: 0 | AH10: 15.5 | AI10: 0 | AJ10: 0.31 | AK10: 15.81 | AL10: 225.18 | AM10: No | AN10: 2.043 | AO10: Yes | AP10: No | AR10: 206500dc-ba9e-4a58-be62-bb3f830ec1f3 | AS10: No | AW10: Yes | AX10: No
A11: 215678515758411 | C11: 2025-09-01 12:11:55 | D11: delivered | E11: regular | H11: PARTY | I11: 1365 | J11: 45 | K11: 136.5 | L11: 0 | M11: 136.5 | N11: 1273.5 | O11: 63.68 | P11: 1337.18 | Q11: 1337.18 | R11: 16.0% | S11: 213.95 | T11: 0 | U11: 0 | V11: 0 | W11: 0 | X11: 0 | Y11: 0 | Z11: 0 | AA11: 0 | AB11: 0 | AC11: 38.52 | AD11: 252.47 | AE11: 0 | AF11: 0 | AG11: 0 | AH11: 63.67 | AI11: 0 | AJ11: 1.27 | AK11: 64.94 | AL11: 1019.77 | AM11: No | AN11: 3.657 | AO11: Yes | AP11: No | AR11: 206500dc-ba9e-4a58-be62-bb3f830ec1f3,206500dc-ba9e-4a58-be62-bb3f830ec1f3 | AS11: No | AW11: Yes | AX11: No
A12: 215678655895729 | C12: 2025-09-01 12:14:15 | D12: delivered | E12: regular | H12: SWIGGYIT | I12: 495 | J12: 20 | K12: 64 | L12: 0 | M12: 64 | N12: 451 | O12: 22.56 | P12: 473.56 | Q12: 473.56 | R12: 22.0% | S12: 104.18 | T12: 0 | U12: 0 | V12: 0 | W12: 0 | X12: 0 | Y12: 0 | Z12: 0 | AA12: 0 | AB12: 0 | AC12: 18.76 | AD12: 122.94 | AE12: 0 | AF12: 0 | AG12: 0 | AH12: 22.55 | AI12: 0 | AJ12: 0.45 | AK12: 23 | AL12: 327.63 | AM12: No | AN12: 2.741 | AO12: Yes | AP12: No | AR12: 206500dc-ba9e-4a58-be62-bb3f830ec1f3,206500dc-ba9e-4a58-be62-bb3f830ec1f3 | AS12: No | AW12: Yes | AX12: No
A13: 215678880211013 | C13: 2025-09-01 12:18:00 | D13: delivered | E13: regular | H13: FLAVORFUL | I13: 880 | J13: 39 | K13: 99.99 | L13: 0 | M13: 99.99 | N13: 819.01 | O13: 40.96 | P13: 859.968 | Q13: 859.97 | R13: 20.0% | S13: 171.99 | T13: 0 | U13: 0 | V13: 0 | W13: 0 | X13: 0 | Y13: 0 | Z13: 0 | AA13: 0 | AB13: 0 | AC13: 30.96 | AD13: 202.95 | AE13: 0 | AF13: 0 | AG13: 0 | AH13: 40.95 | AI13: 0 | AJ13: 0.82 | AK13: 41.77 | AL13: 615.24 | AM13: No | AN13: 3.71 | AO13: Yes | AP13: No | AR13: 206500dc-ba9e-4a58-be62-bb3f830ec1f3,206500dc-ba9e-4a58-be62-bb3f830ec1f3 | AS13: No | AW13: Yes | AX13: No
A14: 215679064037381 | C14: 2025-09-01 12:21:04 | D14: delivered | E14: regular | H14: TRYNEW | I14: 395 | J14: 15 | K14: 64 | L14: 0 | M14: 64 | N14: 346 | O14: 17.3 | P14: 363.3 | Q14: 363.3 | R14: 22.0% | S14: 79.93 | T14: 0 | U14: 0 | V14: 0 | W14: 0 | X14: 0 | Y14: 0 | Z14: 0 | AA14: 0 | AB14: 0 | AC14: 14.38 | AD14: 94.31 | AE14: 0 | AF14: 0 | AG14: 0 | AH14: 17.3 | AI14: 0 | AJ14: 0.35 | AK14: 17.65 | AL14: 251.33 | AM14: No | AN14: 2.741 | AO14: Yes | AP14: No | AR14: 206500dc-ba9e-4a58-be62-bb3f830ec1f3,206500dc-ba9e-4a58-be62-bb3f830ec1f3 | AS14: No | AW14: Yes | AX14: No
A15: 215679187221684 | C15: 2025-09-01 12:23:07 | D15: delivered | E15: regular | H15: TRYNEW | I15: 445 | J15: 15 | K15: 64 | L15: 0 | M15: 64 | N15: 396 | O15: 19.8 | P15: 415.8 | Q15: 415.8 | R15: 22.0% | S15: 91.48 | T15: 0 | U15: 0 | V15: 0 | W15: 0 | X15: 0 | Y15: 0 | Z15: 0 | AA15: 0 | AB15: 0 | AC15: 16.46 | AD15: 107.94 | AE15: 0 | AF15: 0 | AG15: 0 | AH15: 19.8 | AI15: 0 | AJ15: 0.4 | AK15: 20.2 | AL15: 287.65 | AM15: No | AN15: 2.857 | AO15: Yes | AP15: No | AR15: 206500dc-ba9e-4a58-be62-bb3f830ec1f3,206500dc-ba9e-4a58-be62-bb3f830ec1f3 | AS15: No | AW15: Yes | AX15: No
A16: 215679212670399 | C16: 2025-09-01 12:23:32 | D16: delivered | E16: regular | H16: SWIGGYIT | I16: 295 | J16: 10 | K16: 64 | L16: 0 | M16: 64 | N16: 241 | O16: 12.06 | P16: 253.06 | Q16: 253.06 | R16: 22.0% | S16: 55.67 | T16: 0 | U16: 0 | V16: 0 | W16: 0 | X16: 0 | Y16: 0 | Z16: 0 | AA16: 0 | AB16: 0 | AC16: 10.02 | AD16: 65.69 | AE16: 0 | AF16: 0 | AG16: 0 | AH16: 12.05 | AI16: 0 | AJ16: 0.24 | AK16: 12.29 | AL16: 175.07 | AM16: No | AN16: 2.768 | AO16: Yes | AP16: No | AR16: 206500dc-ba9e-4a58-be62-bb3f830ec1f3,206500dc-ba9e-4a58-be62-bb3f830ec1f3 | AS16: No | AW16: Yes | AX16: No
A17: 215679346372023 | C17: 2025-09-01 12:25:46 | D17: delivered | E17: regular | H17: TRYNEW | I17: 445 | J17: 15 | K17: 64 | L17: 0 | M17: 64 | N17: 396 | O17: 19.8 | P17: 415.8 | Q17: 415.8 | R17: 22.0% | S17: 91.48 | T17: 7 | U17: 0 | V17: 0 | W17: 0 | X17: 0 | Y17: 0 | Z17: 0 | AA17: 0 | AB17: 0 | AC17: 17.72 | AD17: 116.2 | AE17: 0 | AF17: 0 | AG17: 0 | AH17: 19.8 | AI17: 0 | AJ17: 0.4 | AK17: 20.2 | AL17: 279.39 | AM17: Yes | AN17: 6.685 | AO17: Yes | AP17: No | AR17: 206500dc-ba9e-4a58-be62-bb3f830ec1f3,206500dc-ba9e-4a58-be62-bb3f830ec1f3 | AS17: No | AW17: Yes | AX17: No
A18: 215679415619995 | C18: 2025-09-01 12:26:55 | D18: delivered | E18: regular | I18: 870 | J18: 30 | K18: 0 | L18: 0 | M18: 0 | N18: 900 | O18: 45 | P18: 945 | Q18: 945 | R18: 16.0% | S18: 151.2 | T18: 0 | U18: 0 | V18: 0 | W18: 0 | X18: 0 | Y18: 0 | Z18: 0 | AA18: 0 | AB18: 0 | AC18: 27.22 | AD18: 178.42 | AE18: 0 | AF18: 0 | AG18: 0 | AH18: 45 | AI18: 0 | AJ18: 0.9 | AK18: 45.9 | AL18: 720.68 | AM18: No | AN18: 4.281 | AO18: Yes | AP18: No | AR18: bf7dde31-1f03-438b-8c83-4e934e8fdc40,206500dc-ba9e-4a58-be62-bb3f830ec1f3 | AS18: No | AW18: Yes | AX18: No
A19: 215679549635390 | C19: 2025-09-01 12:29:09 | D19: delivered | E19: regular | I19: 505 | J19: 22 | K19: 0 | L19: 0 | M19: 0 | N19: 527 | O19: 26.36 | P19: 553.36 | Q19: 553.36 | R19: 20.0% | S19: 110.67 | T19: 12 | U19: 0 | V19: 0 | W19: 0 | X19: 0 | Y19: 0 | Z19: 0 | AA19: 0 | AB19: 0 | AC19: 22.08 | AD19: 144.75 | AE19: 0 | AF19: 0 | AG19: 0 | AH19: 26.35 | AI19: 0 | AJ19: 0.53 | AK19: 26.88 | AL19: 381.72 | AM19: Yes | AN19: 8.282 | AO19: Yes | AP19: No | AS19: No | AW19: Yes | AX19: No
A20: 215679572043008 | C20: 2025-09-01 12:29:32 | D20: delivered | E20: regular | H20: FLAVORFUL | I20: 1195 | J20: 45 | K20: 99.98 | L20: 0 | M20: 99.98 | N20: 1140.02 | O20: 57 | P20: 1197.016 | Q20: 1197.02 | R20: 16.0% | S20: 191.52 | T20: 0 | U20: 0 | V20: 0 | W20: 0 | X20: 0 | Y20: 0 | Z20: 0 | AA20: 0 | AB20: 0 | AC20: 34.48 | AD20: 226 | AE20: 0 | AF20: 0 | AG20: 0 | AH20: 57 | AI20: 0 | AJ20: 1.14 | AK20: 58.14 | AL20: 912.89 | AM20: No | AN20: 5.009 | AO20: Yes | AP20: No | AR20: 6914cfae-bb51-40ca-99a1-0ec7555ec922,206500dc-ba9e-4a58-be62-bb3f830ec1f3,6914cfae-bb51-40ca-99a1-0ec7555ec922,206500dc-ba9e-4a58-be62-bb3f830ec1f3 | AS20: No | AW20: Yes | AX20: No
A21: 215679830114524 | C21: 2025-09-01 12:33:50 | D21: delivered | E21: regular | H21: TRYNEW | I21: 375 | J21: 15 | K21: 64 | L21: 0 | M21: 64 | N21: 326 | O21: 16.3 | P21: 342.3 | Q21: 342.3 | R21: 22.0% | S21: 75.31 | T21: 0 | U21: 0 | V21: 0 | W21: 0 | X21: 0 | Y21: 0 | Z21: 0 | AA21: 0 | AB21: 0 | AC21: 13.56 | AD21: 88.87 | AE21: 0 | AF21: 0 | AG21: 0 | AH21: 16.3 | AI21: 0 | AJ21: 0.33 | AK21: 16.63 | AL21: 236.81 | AM21: No | AN21: 3.415 | AO21: Yes | AP21: No | AR21: 206500dc-ba9e-4a58-be62-bb3f830ec1f3,206500dc-ba9e-4a58-be62-bb3f830ec1f3 | AS21: No | AW21: Yes | AX21: No
A22: 215679923956471 | C22: 2025-09-01 12:35:23 | D22: delivered | E22: regular | H22: WELCOMEBITE | I22: 275 | J22: 10 | K22: 64 | L22: 0 | M22: 64 | N22: 221 | O22: 11.06 | P22: 232.06 | Q22: 232.06 | R22: 22.0% | S22: 51.05 | T22: 0 | U22: 0 | V22: 0 | W22: 0 | X22: 0 | Y22: 0 | Z22: 0 | AA22: 0 | AB22: 0 | AC22: 9.18 | AD22: 60.23 | AE22: 0 | AF22: 0 | AG22: 0 | AH22: 11.05 | AI22: 0 | AJ22: 0.22 | AK22: 11.27 | AL22: 160.53 | AM22: No | AN22: 2.768 | AO22: Yes | AP22: No | AQ22: TRYNEW | AR22: 206500dc-ba9e-4a58-be62-bb3f830ec1f3,153b8f73-eef8-4800-a399-6e532c1bda24,206500dc-ba9e-4a58-be62-bb3f830ec1f3,153b8f73-eef8-4800-a399-6e532c1bda24 | AS22: No | AW22: Yes | AX22: No
A23: 215680160949774 | C23: 2025-09-01 12:39:20 | D23: delivered | E23: regular | H23: SWIGGYIT | I23: 575 | J23: 22 | K23: 63.99 | L23: 0 | M23: 63.99 | N23: 533.01 | O23: 26.66 | P23: 559.668 | Q23: 559.67 | R23: 20.0% | S23: 111.93 | T23: 0 | U23: 0 | V23: 0 | W23: 0 | X23: 0 | Y23: 0 | Z23: 0 | AA23: 0 | AB23: 0 | AC23: 20.14 | AD23: 132.07 | AE23: 0 | AF23: 0 | AG23: 0 | AH23: 26.65 | AI23: 0 | AJ23: 0.53 | AK23: 27.18 | AL23: 400.39 | AM23: No | AN23: 2.101 | AO23: Yes | AP23: No | AR23: 206500dc-ba9e-4a58-be62-bb3f830ec1f3,206500dc-ba9e-4a58-be62-bb3f830ec1f3 | AS23: No | AW23: Yes | AX23: No
A24: 215680429434372 | C24: 2025-09-01 12:43:49 | D24: delivered | E24: regular | H24: SWIGGYIT | I24: 495 | J24: 15 | K24: 64 | L24: 0 | M24: 64 | N24: 446 | O24: 22.3 | P24: 468.3 | Q24: 468.3 | R24: 22.0% | S24: 103.03 | T24: 0 | U24: 0 | V24: 0 | W24: 0 | X24: 0 | Y24: 0 | Z24: 0 | AA24: 0 | AB24: 0 | AC24: 18.54 | AD24: 121.57 | AE24: 0 | AF24: 0 | AG24: 0 | AH24: 22.3 | AI24: 0 | AJ24: 0.45 | AK24: 22.75 | AL24: 323.97 | AM24: No | AN24: 2.752 | AO24: Yes | AP24: No | AR24: d2721a30-5138-4b0f-8bfb-f14ce57ac577,d2721a30-5138-4b0f-8bfb-f14ce57ac577 | AS24: No | AW24: Yes | AX24: No
A25: 215680536650949 | C25: 2025-09-01 12:45:36 | D25: delivered | E25: regular | I25: 1020 | J25: 30 | K25: 0 | L25: 0 | M25: 0 | N25: 1050 | O25: 52.5 | P25: 1102.5 | Q25: 1102.5 | R25: 16.0% | S25: 176.4 | T25: 0 | U25: 0 | V25: 0 | W25: 0 | X25: 0 | Y25: 0 | Z25: 0 | AA25: 0 | AB25: 0 | AC25: 31.76 | AD25: 208.16 | AE25: 0 | AF25: 0 | AG25: 0 | AH25: 52.5 | AI25: 0 | AJ25: 1.05 | AK25: 53.55 | AL25: 840.81 | AM25: No | AN25: 3.676 | AO25: Yes | AP25: No | AR25: 206500dc-ba9e-4a58-be62-bb3f830ec1f3 | AS25: No | AW25: Yes | AX25: No
A26: 215680787260929 | C26: 2025-09-01 12:49:47 | D26: delivered | E26: regular | I26: 595 | J26: 20 | K26: 0 | L26: 0 | M26: 0 | N26: 615 | O26: 30.76 | P26: 645.76 | Q26: 645.76 | R26: 20.0% | S26: 129.15 | T26: 7 | U26: 0 | V26: 0 | W26: 0 | X26: 0 | Y26: 0 | Z26: 0 | AA26: 0 | AB26: 0 | AC26: 24.5 | AD26: 160.65 | AE26: 0 | AF26: 0 | AG26: 0 | AH26: 30.75 | AI26: 0 | AJ26: 0.61 | AK26: 31.36 | AL26: 453.72 | AM26: Yes | AN26: 7.65 | AO26: Yes | AP26: No | AR26: ce57407d-6f5b-456c-8493-63de62e4740e | AS26: No | AW26: Yes | AX26: No
A27: 215680909672216 | C27: 2025-09-01 12:51:49 | D27: delivered | E27: regular | H27: SWIGGYIT | I27: 495 | J27: 20 | K27: 64 | L27: 0 | M27: 64 | N27: 451 | O27: 22.56 | P27: 473.56 | Q27: 473.56 | R27: 22.0% | S27: 104.18 | T27: 0 | U27: 0 | V27: 0 | W27: 0 | X27: 0 | Y27: 0 | Z27: 0 | AA27: 0 | AB27: 0 | AC27: 18.76 | AD27: 122.94 | AE27: 0 | AF27: 0 | AG27: 0 | AH27: 22.55 | AI27: 0 | AJ27: 0.45 | AK27: 23 | AL27: 327.63 | AM27: No | AN27: 4 | AO27: Yes | AP27: No | AR27: 206500dc-ba9e-4a58-be62-bb3f830ec1f3,206500dc-ba9e-4a58-be62-bb3f830ec1f3 | AS27: No | AW27: Yes | AX27: No
A28: 215681008896589 | C28: 2025-09-01 12:53:28 | D28: delivered | E28: regular | H28: TRYNEW | I28: 445 | J28: 15 | K28: 64 | L28: 0 | M28: 64 | N28: 396 | O28: 19.8 | P28: 415.8 | Q28: 415.8 | R28: 22.0% | S28: 91.48 | T28: 0 | U28: 0 | V28: 0 | W28: 0 | X28: 0 | Y28: 0 | Z28: 0 | AA28: 0 | AB28: 0 | AC28: 16.46 | AD28: 107.94 | AE28: 0 | AF28: 0 | AG28: 0 | AH28: 19.8 | AI28: 0 | AJ28: 0.4 | AK28: 20.2 | AL28: 287.65 | AM28: No | AN28: 4.129 | AO28: Yes | AP28: No | AR28: 206500dc-ba9e-4a58-be62-bb3f830ec1f3,206500dc-ba9e-4a58-be62-bb3f830ec1f3 | AS28: No | AW28: Yes | AX28: No
A29: 215681350514143 | C29: 2025-09-01 12:59:10 | D29: delivered | E29: regular | H29: FLAVORFUL | I29: 1115 | J29: 40 | K29: 99.98 | L29: 0 | M29: 99.98 | N29: 1055.02 | O29: 52.76 | P29: 1107.776 | Q29: 1107.78 | R29: 16.0% | S29: 177.24 | T29: 0 | U29: 0 | V29: 0 | W29: 0 | X29: 0 | Y29: 0 | Z29: 0 | AA29: 0 | AB29: 0 | AC29: 31.9 | AD29: 209.14 | AE29: 0 | AF29: 0 | AG29: 0 | AH29: 52.75 | AI29: 0 | AJ29: 1.06 | AK29: 53.81 | AL29: 844.81 | AM29: No | AN29: 3.503 | AO29: Yes | AP29: No | AR29: 206500dc-ba9e-4a58-be62-bb3f830ec1f3,206500dc-ba9e-4a58-be62-bb3f830ec1f3 | AS29: No | AW29: Yes | AX29: No
A30: 215681433971231 | C30: 2025-09-01 13:00:33 | D30: delivered | E30: regular | H30: SWIGGYIT | I30: 345 | J30: 15 | K30: 64 | L30: 0 | M30: 64 | N30: 296 | O30: 14.8 | P30: 310.8 | Q30: 310.8 | R30: 22.0% | S30: 68.38 | T30: 7 | U30: 0 | V30: 0 | W30: 0 | X30: 0 | Y30: 0 | Z30: 0 | AA30: 0 | AB30: 0 | AC30: 13.56 | AD30: 88.94 | AE30: 0 | AF30: 0 | AG30: 0 | AH30: 14.8 | AI30: 0 | AJ30: 0.3 | AK30: 15.1 | AL30: 206.75 | AM30: Yes | AN30: 6.543 | AO30: Yes | AP30: No | AR30: 206500dc-ba9e-4a58-be62-bb3f830ec1f3,206500dc-ba9e-4a58-be62-bb3f830ec1f3 | AS30: No | AW30: Yes | AX30: No
A31: 215681503976527 | C31: 2025-09-01 13:01:43 | D31: delivered | E31: regular | H31: FLAVORFUL | I31: 950 | J31: 35 | K31: 99.99 | L31: 0 | M31: 99.99 | N31: 885.01 | O31: 44.26 | P31: 929.268 | Q31: 929.27 | R31: 16.0% | S31: 148.68 | T31: 0 | U31: 0 | V31: 0 | W31: 0 | X31: 0 | Y31: 0 | Z31: 0 | AA31: 0 | AB31: 0 | AC31: 26.76 | AD31: 175.44 | AE31: 0 | AF31: 0 | AG31: 0 | AH31: 44.25 | AI31: 0 | AJ31: 0.89 | AK31: 45.14 | AL31: 708.68 | AM31: No | AN31: 5.103 | AO31: Yes | AP31: No | AR31: 419540c2-a8bc-4570-96b4-d4a769aa36da,206500dc-ba9e-4a58-be62-bb3f830ec1f3,419540c2-a8bc-4570-96b4-d4a769aa36da,206500dc-ba9e-4a58-be62-bb3f830ec1f3 | AS31: No | AW31: Yes | AX31: No
A32: 215681683200756 | C32: 2025-09-01 13:04:43 | D32: delivered | E32: regular | H32: SWIGGYIT | I32: 495 | J32: 15 | K32: 64 | L32: 0 | M32: 64 | N32: 446 | O32: 22.3 | P32: 468.3 | Q32: 468.3 | R32: 22.0% | S32: 103.03 | T32: 0 | U32: 0 | V32: 0 | W32: 0 | X32: 0 | Y32: 0 | Z32: 0 | AA32: 0 | AB32: 0 | AC32: 18.54 | AD32: 121.57 | AE32: 0 | AF32: 0 | AG32: 0 | AH32: 22.3 | AI32: 0 | AJ32: 0.45 | AK32: 22.75 | AL32: 323.97 | AM32: No | AN32: 2.741 | AO32: Yes | AP32: No | AR32: 206500dc-ba9e-4a58-be62-bb3f830ec1f3,206500dc-ba9e-4a58-be62-bb3f830ec1f3 | AS32: No | AW32: Yes | AX32: No
A33: 215681766589401 | C33: 2025-09-01 13:06:06 | D33: delivered | E33: regular | H33: TRYNEW | I33: 495 | J33: 15 | K33: 64 | L33: 0 | M33: 64 | N33: 446 | O33: 22.3 | P33: 468.3 | Q33: 468.3 | R33: 22.0% | S33: 103.03 | T33: 0 | U33: 0 | V33: 0 | W33: 0 | X33: 0 | Y33: 0 | Z33: 0 | AA33: 0 | AB33: 0 | AC33: 18.54 | AD33: 121.57 | AE33: 0 | AF33: 0 | AG33: 0 | AH33: 22.3 | AI33: 0 | AJ33: 0.45 | AK33: 22.75 | AL33: 323.97 | AM33: No | AN33: 4.799 | AO33: Yes | AP33: No | AR33: 206500dc-ba9e-4a58-be62-bb3f830ec1f3,206500dc-ba9e-4a58-be62-bb3f830ec1f3 | AS33: No | AW33: Yes | AX33: No
A34: 215682015822241 | C34: 2025-09-01 13:10:15 | D34: delivered | E34: regular | H34: SWIGGYIT | I34: 395 | J34: 15 | K34: 64 | L34: 0 | M34: 64 | N34: 346 | O34: 17.3 | P34: 363.3 | Q34: 363.3 | R34: 22.0% | S34: 79.93 | T34: 0 | U34: 0 | V34: 0 | W34: 0 | X34: 0 | Y34: 0 | Z34: 0 | AA34: 0 | AB34: 0 | AC34: 14.38 | AD34: 94.31 | AE34: 0 | AF34: 0 | AG34: 0 | AH34: 17.3 | AI34: 0 | AJ34: 0.35 | AK34: 17.65 | AL34: 251.33 | AM34: No | AN34: 4.811 | AO34: Yes | AP34: No | AR34: 3d863974-48e1-4952-bcd2-ba7e746255af,206500dc-ba9e-4a58-be62-bb3f830ec1f3,3d863974-48e1-4952-bcd2-ba7e746255af,206500dc-ba9e-4a58-be62-bb3f830ec1f3 | AS34: No | AW34: Yes | AX34: No
A35: 215682027608451 | C35: 2025-09-01 13:10:27 | D35: delivered | E35: regular | H35: SWIGGYIT | I35: 475 | J35: 15 | K35: 64 | L35: 0 | M35: 64 | N35: 426 | O35: 21.3 | P35: 447.3 | Q35: 447.3 | R35: 22.0% | S35: 98.41 | T35: 0 | U35: 0 | V35: 0 | W35: 0 | X35: 0 | Y35: 0 | Z35: 0 | AA35: 0 | AB35: 0 | AC35: 17.72 | AD35: 116.13 | AE35: 0 | AF35: 0 | AG35: 0 | AH35: 21.3 | AI35: 0 | AJ35: 0.43 | AK35: 21.73 | AL35: 309.46 | AM35: No | AN35: 2.901 | AO35: Yes | AP35: No | AR35: 206500dc-ba9e-4a58-be62-bb3f830ec1f3,206500dc-ba9e-4a58-be62-bb3f830ec1f3 | AS35: No | AW35: Yes | AX35: No
A36: 215682147110116 | C36: 2025-09-01 13:12:27 | D36: delivered | E36: regular | H36: TRYNEW | I36: 625 | J36: 29 | K36: 64 | L36: 0 | M36: 64 | N36: 590 | O36: 29.5 | P36: 619.5 | Q36: 619.5 | R36: 20.0% | S36: 123.9 | T36: 0 | U36: 0 | V36: 0 | W36: 0 | X36: 0 | Y36: 0 | Z36: 0 | AA36: 0 | AB36: 0 | AC36: 22.3 | AD36: 146.2 | AE36: 0 | AF36: 0 | AG36: 0 | AH36: 29.5 | AI36: 0 | AJ36: 0.59 | AK36: 30.09 | AL36: 443.21 | AM36: No | AN36: 2.223 | AO36: Yes | AP36: No | AR36: 206500dc-ba9e-4a58-be62-bb3f830ec1f3,206500dc-ba9e-4a58-be62-bb3f830ec1f3 | AS36: No | AW36: Yes | AX36: No
A37: 215682384869780 | C37: 2025-09-01 13:16:24 | D37: delivered | E37: regular | H37: PARTY | I37: 1940 | J37: 81 | K37: 194 | L37: 0 | M37: 194 | N37: 1827 | O37: 91.36 | P37: 1918.36 | Q37: 1918.34 | R37: 14.0% | S37: 268.57 | T37: 0 | U37: 0 | V37: 0 | W37: 0 | X37: 0 | Y37: 0 | Z37: 0 | AA37: 0 | AB37: 0 | AC37: 48.34 | AD37: 316.91 | AE37: 0 | AF37: 0 | AG37: 0 | AH37: 91.35 | AI37: 0 | AJ37: 1.83 | AK37: 93.18 | AL37: 1508.26 | AM37: No | AN37: 2.857 | AO37: Yes | AP37: No | AR37: 206500dc-ba9e-4a58-be62-bb3f830ec1f3,206500dc-ba9e-4a58-be62-bb3f830ec1f3 | AS37: No | AW37: Yes | AX37: No
A38: 215682407670759 | C38: 2025-09-01 13:16:47 | D38: delivered | E38: regular | H38: TRYNEW | I38: 345 | J38: 15 | K38: 64 | L38: 0 | M38: 64 | N38: 296 | O38: 14.8 | P38: 310.8 | Q38: 310.8 | R38: 22.0% | S38: 68.38 | T38: 0 | U38: 0 | V38: 0 | W38: 0 | X38: 0 | Y38: 0 | Z38: 0 | AA38: 0 | AB38: 0 | AC38: 12.3 | AD38: 80.68 | AE38: 0 | AF38: 0 | AG38: 0 | AH38: 14.8 | AI38: 0 | AJ38: 0.3 | AK38: 15.1 | AL38: 215.01 | AM38: No | AN38: 1.856 | AO38: Yes | AP38: No | AR38: 206500dc-ba9e-4a58-be62-bb3f830ec1f3,206500dc-ba9e-4a58-be62-bb3f830ec1f3 | AS38: No | AW38: Yes | AX38: No
... A44: 215683603479812 | C44: 2025-09-01 13:36:43 | D44: delivered | E44: regular | H44: SWIGGYIT | I44: 595 | J44: 20 | K44: 64 | L44: 0 | M44: 64 | N44: 551 | O44: 27.56 | P44: 578.56 | Q44: 578.56 | R44: 20.0% | S44: 115.71 | T44: 7 | U44: 0 | V44: 0 | W44: 0 | X44: 0 | Y44: 0 | Z44: 0 | AA44: 0 | AB44: 0 | AC44: 22.08 | AD44: 144.79 | AE44: 0 | AF44: 0 | AG44: 0 | AH44: 27.55 | AI44: 0 | AJ44: 0.55 | AK44: 28.1 | AL44: 405.64 | AM44: Yes | AN44: 6.885 | AO44: Yes | AP44: No | AR44: 206500dc-ba9e-4a58-be62-bb3f830ec1f3,206500dc-ba9e-4a58-be62-bb3f830ec1f3 | AS44: No | AW44: Yes | AX44: No
A45: 215683732142747 | C45: 2025-09-01 13:38:52 | D45: delivered | E45: regular | I45: 915 | J45: 35 | K45: 0 | L45: 0 | M45: 0 | N45: 950 | O45: 47.5 | P45: 997.5 | Q45: 997.5 | R45: 16.0% | S45: 159.6 | T45: 0 | U45: 0 | V45: 0 | W45: 0 | X45: 0 | Y45: 0 | Z45: 0 | AA45: 0 | AB45: 0 | AC45: 28.72 | AD45: 188.32 | AE45: 0 | AF45: 0 | AG45: 0 | AH45: 47.5 | AI45: 0 | AJ45: 0.95 | AK45: 48.45 | AL45: 760.71 | AM45: No | AN45: 3.536 | AO45: Yes | AP45: No | AS45: No | AW45: No | AX45: No
...

Sheet D2W1
A1: Adjustments this week
A2: Adjustment Type | B2: Total Amount | C2: Settled Amount | D2: Outstanding Amount | E2: Period From | F2: Period To | G2: Invoice Number | H2: Remarks
A3: CPC Ads | B3: ₹-6128.920000000001 | C3: ₹-6128.92 | D3: ₹0.0 | E3: 2025-09-01 | F3: 2025-09-06 | G3: 250910FS36005533 | H3: CPC Ads for service period 01 September 2025 to 06 September 2025
A4: CPC Ads | B4: ₹-7384.440000000001 | C4: ₹-7384.44 | D4: ₹0.0 | E4: 2025-09-01 | F4: 2025-09-06 | G4: 250910FS36005533 | H4: CPC Ads for service period 01 September 2025 to 06 September 2025
A5: CPC Ads | B5: ₹-6574.960000000001 | C5: ₹-6574.96 | D5: ₹0.0 | E5: 2025-09-01 | F5: 2025-09-06 | G5: 250910FS36005533 | H5: CPC Ads for service period 01 September 2025 to 06 September 2025
A6: CPC Ads | B6: ₹-6128.920000000001 | C6: ₹-6128.92 | D6: ₹0.0 | E6: 2025-09-01 | F6: 2025-09-06 | G6: 250910FS36005533 | H6: CPC Ads for service period 01 September 2025 to 06 September 2025
A7: CPC Ads | B7: ₹-6872.320000000001 | C7: ₹-6872.32 | D7: ₹0.0 | E7: 2025-09-01 | F7: 2025-09-06 | G7: 250910FS36005533 | H7: CPC Ads for service period 01 September 2025 to 06 September 2025
A8: CPC Ads | B8: ₹-6574.960000000001 | C8: ₹-6574.96 | D8: ₹0.0 | E8: 2025-09-01 | F8: 2025-09-06 | G8: 250910FS36005533 | H8: CPC Ads for service period 01 September 2025 to 06 September 2025
A10: Adjustments from previous week
A11: Adjusment Type | B11: Total Amount | C11: Settled Amount | D11: Outstanding Amount | E11: Period From | F11: Period To | G11: Invoice Number | H11: Remarks
A13: Total Adjustments | B13: ₹-39664.52 | C13: ₹-39664.52 | D13: ₹0.0

Sheet D1W2
I1: 7905 | J1: 260 | K1: 676.99 | L1: 0 | M1: 676.99 | N1: 7488.01 | O1: 293.7 | P1: 7781.708 | Q1: 4280.282 | R1: 0 | S1: 413.61 | T1: 0 | U1: 0 | V1: 0 | W1: 0 | X1: 0 | Y1: 0 | Z1: 0 | AA1: 0 | AB1: 0 | AC1: 74.46 | AD1: 488.07 | AE1: 3469.09 | AF1: 0 | AG1: 3469.09 | AH1: 205.36 | AI1: 0 | AJ1: 1.94 | AK1: 207.3 | AL1: 3617.21 | AM1: 0 | AN1: 55.996 | AO1: 0 | AP1: 0 | AQ1: 0 | AR1: 0 | AS1: 0 | AT1: 0 | AU1: 387.05 | AV1: 0 | AW1: 0 | AX1: 0 | AY1: 0 | AZ1: 0 | BA1: 0 | BB1: 0 | BC1: 0 | BD1: 0 | BE1: 0 | BF1: 0 | BG1: 0 | BH1: 0 | BI1: 0 | BJ1: 0 | BK1: 0 | BL1: 0 | BM1: 0 | BN1: 0 | BO1: 0 | BP1: 0 | BQ1: 0 | BR1: 0 | BS1: 0 | BT1: 0 | BU1: 0 | BV1: 0 | BW1: 0 | BX1: 0 | BY1: 0 | BZ1: 0 | CA1: 0 | CB1: 0 | CC1: 0
I2: 1061160 | J2: 38491 | K2: 107304.54 | L2: 2104.83 | M2: 109409.37 | N2: 990241.63 | O2: 49515.96 | P2: 1039756.9 | Q2: 1039756.6 | R2: 0 | S2: 182814.11 | T2: 4850 | U2: 0 | V2: 0 | W2: 0 | X2: 0 | Y2: 0 | Z2: 0 | AA2: 0 | AB2: 0 | AC2: 33777.42 | AD2: 221441.53 | AE2: 0 | AF2: 4174 | AG2: 4174 | AH2: 49511.86 | AI2: 0 | AJ2: 992.68 | AK2: 50504.54 | AL2: 763629.92 | AM2: 0 | AN2: 7068.814 | AO2: 0 | AP2: 0 | AQ2: 0 | AR2: 0 | AS2: 0 | AT2: 0 | AU2: 0 | AV2: 0 | AW2: 0 | AX2: 0 | AY2: 0 | AZ2: 0 | BA2: 0 | BB2: 0 | BC2: 0 | BD2: 0 | BE2: 0 | BF2: 0 | BG2: 0 | BH2: 0 | BI2: 0 | BJ2: 0 | BK2: 0 | BL2: 0 | BM2: 0 | BN2: 0 | BO2: 0 | BP2: 0 | BQ2: 0 | BR2: 0 | BS2: 0 | BT2: 0 | BU2: 0 | BV2: 0 | BW2: 0 | BX2: 0 | BY2: 0 | BZ2: 0 | CA2: 0 | CB2: 0 | CC2: 0
I3: 1261496.7 | J3: 45726.18 | K3: 127418.21 | L3: 2483.6994 | M3: 129901.9 | N3: 1177321 | O3: 58775.399 | P3: 1236095.5 | Q3: 1231963.5 | R3: 0 | S3: 216208.71 | T3: 5723 | U3: 0 | V3: 0 | W3: 0 | X3: 0 | Y3: 0 | Z3: 0 | AA3: 0 | AB3: 0 | AC3: 39945.218 | AD3: 261876.93 | AE3: 4093.5262 | AF3: 4925.32 | AG3: 9018.8462 | AH3: 58666.32 | AI3: 0 | AJ3: 1173.6516 | AK3: 59839.971 | AL3: 905351.61 | AM3: 0 | AN3: 8407.2758 | AO3: 0 | AP3: 0 | AQ3: 0 | AR3: 0 | AS3: 0 | AT3: 0 | AU3: 456.719 | AV3: 0 | AW3: 0 | AX3: 0 | AY3: 0 | AZ3: 0 | BA3: 0 | BB3: 0 | BC3: 0 | BD3: 0 | BE3: 0 | BF3: 0 | BG3: 0 | BH3: 0 | BI3: 0 | BJ3: 0 | BK3: 0 | BL3: 0 | BM3: 0 | BN3: 0 | BO3: 0 | BP3: 0 | BQ3: 0 | BR3: 0 | BS3: 0 | BT3: 0 | BU3: 0 | BV3: 0 | BW3: 0 | BX3: 0 | BY3: 0 | BZ3: 0 | CA3: 0 | CB3: 0 | CC3: 0
I4: 1069065 | J4: 38751 | K4: 107981.53 | L4: 2104.83 | M4: 110086.36 | N4: 997729.64 | O4: 49809.66 | P4: 1047538.6 | Q4: 1044036.8 | R4: 0 | S4: 183227.72 | T4: 4850 | U4: 0 | V4: 0 | W4: 0 | X4: 0 | Y4: 0 | Z4: 0 | AA4: 0 | AB4: 0 | AC4: 33851.88 | AD4: 221929.6 | AE4: 3469.09 | AF4: 4174 | AG4: 7643.09 | AH4: 49717.22 | AI4: 0 | AJ4: 994.62 | AK4: 50711.84 | AL4: 767247.13 | AM4: 0 | AN4: 7124.81 | AO4: 0 | AP4: 0 | AQ4: 0 | AR4: 0 | AS4: 0 | AT4: 0 | AU4: 387.05 | AV4: 0 | AW4: 0 | AX4: 0 | AY4: 0 | AZ4: 0 | BA4: 0 | BB4: 0 | BC4: 0 | BD4: 0 | BE4: 0 | BF4: 0 | BG4: 0 | BH4: 0 | BI4: 0 | BJ4: 0 | BK4: 0 | BL4: 0 | BM4: 0 | BN4: 0 | BO4: 0 | BP4: 0 | BQ4: 0 | BR4: 0 | BS4: 0 | BT4: 0 | BU4: 0 | BV4: 0 | BW4: 0 | BX4: 0 | BY4: 0 | BZ4: 0 | CA4: 0 | CB4: 0 | CC4: 0
A5: Order ID | B5: Parent Order ID | C5: Order Date | D5: Order Status | E5: Order Category | F5: Order Payment Type | G5: Cancelled By? | H5: Coupon type applied by customer | I5: Item Total | J5: Packaging Charges | K5: Restaurant Discounts (Promo, Freebies, Flat Off, etc.) | L5: Swiggy One Exclusive Offer Discount | M5: Restaurant Discount Share [3a+3b] | N5: Net Bill Value (before taxes) [1+2-3] | O5: GST Collected | P5: Total Customer Paid [4+5] | Q5: Commission charged on | R5: Service Fees % | S5: Commission | T5: Long Distance Charges | U5: Discount on Long Distance Fee | V5: Pocket Hero Fees | W5: Swiggy One Fees | X5: Payment Collection Charges | Y5: Restaurant Cancellation Charges | Z5: Call Center Charges | AA5: Delivery Fee sponsored by Restaurant (w/o tax) | AB5: Bolt Fees | AC5: GST on Service Fee @18% | AD5: Total Swiggy Fees [6+7+8-9+10+11+12+13+14+15+16] | AE5: Customer Cancellations | AF5: Customer Complaints | AG5: Complaint & Cancellation Charges [17+18] | AH5: GST Deduction | AI5: TCS | AJ5: TDS | AK5: Total Taxes [19+20+21] | AL5: Net Payout for Order (after taxes) [A-B-C-D] | AM5: Long Distance Order | AN5: Last Mile (in km) | AO5: MFR Accurate? | AP5: MFR Pressed? | AQ5: Coupon Code Sourced | AR5: Discount Campaign ID | AS5: Replicated Order | AT5: Base order ID | AU5: Cancellation time | AV5: Pick Up Status | AW5: Swiggy One Customer? | AX5: Pocket Hero Order?
A6: 216195415833927 | C6: 2025-09-07 11:46:55 | D6: delivered | E6: regular | H6: ORDERON | I6: 445 | J6: 15 | K6: 64 | L6: 0 | M6: 64 | N6: 396 | O6: 19.8 | P6: 415.8 | Q6: 415.8 | R6: 22.0% | S6: 91.48 | T6: 20 | U6: 0 | V6: 0 | W6: 0 | X6: 0 | Y6: 0 | Z6: 0 | AA6: 0 | AB6: 0 | AC6: 20.06 | AD6: 131.54 | AE6: 0 | AF6: 0 | AG6: 0 | AH6: 19.8 | AI6: 0 | AJ6: 0.4 | AK6: 20.2 | AL6: 264.05 | AM6: Yes | AN6: 10.584 | AO6: Yes | AP6: No | AQ6: SWIGGYIT | AR6: 100833489 | AS6: No | AW6: Yes | AX6: No
A7: 216195624955525 | C7: 2025-09-07 11:50:24 | D7: delivered | E7: regular | H7: MISSEDYOU | I7: 545 | J7: 20 | K7: 64 | L7: 0 | M7: 64 | N7: 501 | O7: 25.06 | P7: 526.06 | Q7: 526.06 | R7: 20.0% | S7: 105.21 | T7: 0 | U7: 0 | V7: 0 | W7: 0 | X7: 0 | Y7: 0 | Z7: 0 | AA7: 0 | AB7: 0 | AC7: 18.94 | AD7: 124.15 | AE7: 0 | AF7: 0 | AG7: 0 | AH7: 25.05 | AI7: 0 | AJ7: 0.5 | AK7: 25.55 | AL7: 376.35 | AM7: No | AN7: 3.221 | AO7: Yes | AP7: No | AR7: 206500dc-ba9e-4a58-be62-bb3f830ec1f3,206500dc-ba9e-4a58-be62-bb3f830ec1f3 | AS7: No | AW7: Yes | AX7: No
A8: 216196251207859 | C8: 2025-09-07 12:00:51 | D8: delivered | E8: regular | H8: MISSEDYOU | I8: 595 | J8: 20 | K8: 64 | L8: 0 | M8: 64 | N8: 551 | O8: 27.56 | P8: 578.56 | Q8: 578.56 | R8: 20.0% | S8: 115.71 | T8: 0 | U8: 0 | V8: 0 | W8: 0 | X8: 0 | Y8: 0 | Z8: 0 | AA8: 0 | AB8: 0 | AC8: 20.82 | AD8: 136.53 | AE8: 0 | AF8: 0 | AG8: 0 | AH8: 27.55 | AI8: 0 | AJ8: 0.55 | AK8: 28.1 | AL8: 413.9 | AM8: No | AN8: 1.736 | AO8: Yes | AP8: No | AR8: 206500dc-ba9e-4a58-be62-bb3f830ec1f3,206500dc-ba9e-4a58-be62-bb3f830ec1f3 | AS8: No | AW8: Yes | AX8: No
A9: 216196318782234 | C9: 2025-09-07 12:01:58 | D9: delivered | E9: regular | H9: FLAVORFUL | I9: 795 | J9: 20 | K9: 100 | L9: 0 | M9: 100 | N9: 715 | O9: 35.76 | P9: 750.76 | Q9: 750.76 | R9: 20.0% | S9: 150.15 | T9: 7 | U9: 0 | V9: 0 | W9: 0 | X9: 0 | Y9: 0 | Z9: 0 | AA9: 0 | AB9: 0 | AC9: 28.28 | AD9: 185.43 | AE9: 0 | AF9: 0 | AG9: 0 | AH9: 35.75 | AI9: 0 | AJ9: 0.71 | AK9: 36.46 | AL9: 528.84 | AM9: Yes | AN9: 7.14 | AO9: Yes | AP9: No | AR9: 206500dc-ba9e-4a58-be62-bb3f830ec1f3,206500dc-ba9e-4a58-be62-bb3f830ec1f3 | AS9: No | AW9: Yes | AX9: No
A10: 216196319730615 | C10: 2025-09-07 12:01:59 | D10: delivered | E10: regular | H10: TOPUPOFFER | I10: 1070 | J10: 40 | K10: 63.99 | L10: 0 | M10: 63.99 | N10: 1046.01 | O10: 52.3 | P10: 1098.308 | Q10: 1098.31 | R10: 16.0% | S10: 175.73 | T10: 12 | U10: 0 | V10: 0 | W10: 0 | X10: 0 | Y10: 0 | Z10: 0 | AA10: 0 | AB10: 0 | AC10: 33.8 | AD10: 221.53 | AE10: 0 | AF10: 0 | AG10: 0 | AH10: 52.3 | AI10: 0 | AJ10: 1.05 | AK10: 53.35 | AL10: 823.45 | AM10: Yes | AN10: 8.672 | AO10: Yes | AP10: No | AQ10: SWIGGYIT | AR10: 100833489 | AS10: No | AW10: Yes | AX10: No
A11: 216196369395491 | C11: 2025-09-07 12:02:49 | D11: delivered | E11: regular | H11: FLAVORFUL | I11: 1070 | J11: 35 | K11: 99.99 | L11: 0 | M11: 99.99 | N11: 1005.01 | O11: 50.26 | P11: 1055.268 | Q11: 1055.27 | R11: 16.0% | S11: 168.84 | T11: 12 | U11: 0 | V11: 0 | W11: 0 | X11: 0 | Y11: 0 | Z11: 0 | AA11: 0 | AB11: 0 | AC11: 32.56 | AD11: 213.4 | AE11: 0 | AF11: 0 | AG11: 0 | AH11: 50.25 | AI11: 0 | AJ11: 1.01 | AK11: 51.26 | AL11: 790.62 | AM11: Yes | AN11: 8.357 | AO11: Yes | AP11: No | AR11: 103197863 | AS11: No | AW11: Yes | AX11: No
A12: 216196370342633 | C12: 2025-09-07 12:02:50 | D12: delivered | E12: regular | H12: PARTY | I12: 3720 | J12: 130 | K12: 372 | L12: 0 | M12: 372 | N12: 3478 | O12: 173.9 | P12: 3651.9 | Q12: 3651.9 | R12: 10.0% | S12: 365.19 | T12: 0 | U12: 0 | V12: 0 | W12: 0 | X12: 0 | Y12: 0 | Z12: 0 | AA12: 0 | AB12: 0 | AC12: 65.74 | AD12: 430.93 | AE12: 0 | AF12: 0 | AG12: 0 | AH12: 173.9 | AI12: 0 | AJ12: 3.48 | AK12: 177.38 | AL12: 3043.61 | AM12: No | AN12: 2.165 | AO12: Yes | AP12: No | AR12: 206500dc-ba9e-4a58-be62-bb3f830ec1f3,206500dc-ba9e-4a58-be62-bb3f830ec1f3 | AS12: No | AW12: Yes | AX12: No
A13: 216196398579170 | C13: 2025-09-07 12:03:18 | D13: delivered | E13: regular | H13: PARTY | I13: 2505 | J13: 101 | K13: 250.5 | L13: 0 | M13: 250.5 | N13: 2355.5 | O13: 117.78 | P13: 2473.28 | Q13: 2473.28 | R13: 12.0% | S13: 296.79 | T13: 0 | U13: 0 | V13: 0 | W13: 0 | X13: 0 | Y13: 0 | Z13: 0 | AA13: 0 | AB13: 0 | AC13: 53.42 | AD13: 350.21 | AE13: 0 | AF13: 0 | AG13: 0 | AH13: 117.78 | AI13: 0 | AJ13: 2.36 | AK13: 120.14 | AL13: 2002.93 | AM13: No | AN13: 4.025 | AO13: Yes | AP13: No | AR13: 206500dc-ba9e-4a58-be62-bb3f830ec1f3,206500dc-ba9e-4a58-be62-bb3f830ec1f3 | AS13: No | AW13: Yes | AX13: No
A14: 216196406085506 | C14: 2025-09-07 12:03:26 | D14: delivered | E14: regular | I14: 750 | J14: 30 | K14: 0 | L14: 0 | M14: 0 | N14: 780 | O14: 39 | P14: 819 | Q14: 819 | R14: 20.0% | S14: 163.8 | T14: 0 | U14: 0 | V14: 0 | W14: 0 | X14: 0 | Y14: 0 | Z14: 0 | AA14: 0 | AB14: 0 | AC14: 29.48 | AD14: 193.28 | AE14: 0 | AF14: 0 | AG14: 0 | AH14: 39 | AI14: 0 | AJ14: 0.78 | AK14: 39.78 | AL14: 585.94 | AM14: No | AN14: 2.887 | AO14: Yes | AP14: No | AS14: No | AW14: No | AX14: No
